Workbook
Name SegmentaciónDeDatos_SKU: #N/A

Sheet pivot table
B3: Producto | C3: Forecast (Und) | D3: Pedidos (Und) | E3: WMAPE | F3: MAPE % | G3: Bias %
B4: SKU1 | C4: 122714.03 | D4: 123900 | E4: 0.22179605 | F4: 0.0095720257 | G4: 0.073891273
B5: SKU10 | C5: 7242.8142 | D5: 6600 | E5: 0.26602729 | F5: 0.097396096 | G5: 0.26542119
B6: SKU11 | C6: 6875.4436 | D6: 7320 | E6: 0.28010844 | F6: 0.060731752 | G6: 0.035646342
B7: SKU12 | C7: 4296.7154 | D7: 4740 | E7: 0.46064403 | F7: 0.09351995 | G7: 0.21443637
B8: SKU13 | C8: 4166.7175 | D8: 3660 | E8: 0.3078787 | F8: 0.13844739 | G8: 0.41185596
B9: SKU14 | C9: 15622.453 | D9: 11880 | E9: 0.55347955 | F9: 0.31502131 | G9: 1.0356156
B10: SKU15 | C10: 5008.7889 | D10: 5040 | E10: 0.4294561 | F10: 0.0061926856 | G10: 0.24931943
B11: SKU16 | C11: 24762.358 | D11: 25050 | E11: 0.17311989 | F11: 0.01148272 | G11: 0.028041241
B12: SKU17 | C12: 70194.863 | D12: 64800 | E12: 0.25732444 | F12: 0.083254054 | G12: 0.17376842
B13: SKU18 | C13: 1092.1316 | D13: 3000 | E13: 0.63595612 | F13: 0.63595612 | G13: -0.73232067
B14: SKU19 | C14: 22039.023 | D14: 19200 | E14: 0.56139859 | F14: 0.14786579 | G14: 0.64279354
B15: SKU2 | C15: 30463.067 | D15: 27450 | E15: 0.25224473 | F15: 0.10976565 | G15: 0.23632355
... B30: Total general | C30: 835389.57 | D30: 775116 | E30: 0.30780125 | F30: 0.077760707 | G30: 0.27143036

Sheet transformed data
A2: # | B2: SKU | C2: Best_Model | D2: MAE | E2: RMSE | F2: MAPE | G2: Group | H2: WD1 | I2: WD2 | J2: WD3 | K2: WD4 | L2: WD5 | M2: WD6 | N2: WD7 | O2: Total
A3: 1 | B3: SKU1 | C3: HW-add-add-a0.2-b0.8-g0.2 | D3: 3925.79 | E3: 4127.5524 | F3: 25.569422 | G3: Forecast | H3: =_xlfn.XLOOKUP($B3,'raw data'!$A:$A,'raw data'!F:F) -> 20140.043 | I3: =_xlfn.XLOOKUP($B3,'raw data'!$A:$A,'raw data'!G:G) -> 14303.797 | J3: =_xlfn.XLOOKUP($B3,'raw data'!$A:$A,'raw data'!H:H) -> 11260.913 | K3: =_xlfn.XLOOKUP($B3,'raw data'!$A:$A,'raw data'!I:I) -> 19622.907 | L3: =_xlfn.XLOOKUP($B3,'raw data'!$A:$A,'raw data'!J:J) -> 9156.662 | M3: =_xlfn.XLOOKUP($B3,'raw data'!$A:$A,'raw data'!K:K) -> 26757.109 | N3: =_xlfn.XLOOKUP($B3,'raw data'!$A:$A,'raw data'!L:L) -> 21472.594 | O3: =SUM(H3:N3) -> 122714.03
B4: SKU1 | G4: Pedidos | H4: 25800 | I4: 19800 | J4: 9000 | K4: 22800 | L4: 6000 | M4: 21900 | N4: 18600 | O4: =SUM(H4:N4) -> 123900
A5: 2 | B5: SKU2 | C5: HW-None-add-a0.8-b0.2-g0.2 | D5: 989.1597 | E5: 1182.2892 | F5: 34.357924 | G5: Forecast | H5: =_xlfn.XLOOKUP($B5,'raw data'!$A:$A,'raw data'!F:F) -> 3995.1376 | I5: =_xlfn.XLOOKUP($B5,'raw data'!$A:$A,'raw data'!G:G) -> 4607.4319 | J5: =_xlfn.XLOOKUP($B5,'raw data'!$A:$A,'raw data'!H:H) -> 3889.8667 | K5: =_xlfn.XLOOKUP($B5,'raw data'!$A:$A,'raw data'!I:I) -> 5076.707 | L5: =_xlfn.XLOOKUP($B5,'raw data'!$A:$A,'raw data'!J:J) -> 3866.023 | M5: =_xlfn.XLOOKUP($B5,'raw data'!$A:$A,'raw data'!K:K) -> 4787.2011 | N5: =_xlfn.XLOOKUP($B5,'raw data'!$A:$A,'raw data'!L:L) -> 4240.6997 | O5: =SUM(H5:N5) -> 30463.067
B6: SKU2 | G6: Pedidos | H6: 2250 | I6: 3000 | J6: 4500 | K6: 5250 | L6: 2250 | M6: 5850 | N6: 4350 | O6: =SUM(H6:N6) -> 27450
A7: 3 | B7: SKU3 | C7: HW-None-mul-a0.2-b0.2-g0.2 | D7: 4618.5295 | E7: 5226.9589 | F7: 64.93872 | G7: Forecast | H7: =_xlfn.XLOOKUP($B7,'raw data'!$A:$A,'raw data'!F:F) -> 13309.391 | I7: =_xlfn.XLOOKUP($B7,'raw data'!$A:$A,'raw data'!G:G) -> 15675.103 | J7: =_xlfn.XLOOKUP($B7,'raw data'!$A:$A,'raw data'!H:H) -> 14702.795 | K7: =_xlfn.XLOOKUP($B7,'raw data'!$A:$A,'raw data'!I:I) -> 18112.467 | L7: =_xlfn.XLOOKUP($B7,'raw data'!$A:$A,'raw data'!J:J) -> 12228.802 | M7: =_xlfn.XLOOKUP($B7,'raw data'!$A:$A,'raw data'!K:K) -> 18106.326 | N7: =_xlfn.XLOOKUP($B7,'raw data'!$A:$A,'raw data'!L:L) -> 12800.412 | O7: =SUM(H7:N7) -> 104935.3
B8: SKU3 | G8: Pedidos | H8: 6000 | I8: 9000 | J8: 18000 | K8: 15000 | L8: 4200 | M8: 15600 | N8: 11400 | O8: =SUM(H8:N8) -> 79200
A9: 4 | B9: SKU4 | C9: HW-add-add-a0.2-b0.2-g0.2 | D9: 1220.2418 | E9: 1466.6587 | F9: 32.756127 | G9: Forecast | H9: =_xlfn.XLOOKUP($B9,'raw data'!$A:$A,'raw data'!F:F) -> 4957.4492 | I9: =_xlfn.XLOOKUP($B9,'raw data'!$A:$A,'raw data'!G:G) -> 4961.8858 | J9: =_xlfn.XLOOKUP($B9,'raw data'!$A:$A,'raw data'!H:H) -> 4933.28 | K9: =_xlfn.XLOOKUP($B9,'raw data'!$A:$A,'raw data'!I:I) -> 6242.4814 | L9: =_xlfn.XLOOKUP($B9,'raw data'!$A:$A,'raw data'!J:J) -> 3715.7896 | M9: =_xlfn.XLOOKUP($B9,'raw data'!$A:$A,'raw data'!K:K) -> 5772.054 | N9: =_xlfn.XLOOKUP($B9,'raw data'!$A:$A,'raw data'!L:L) -> 4654.3835 | O9: =SUM(H9:N9) -> 35237.324
B10: SKU4 | G10: Pedidos | H10: 3000 | I10: 4500 | J10: 7500 | K10: 6750 | L10: 1950 | M10: 6750 | N10: 4350 | O10: =SUM(H10:N10) -> 34800
A11: 5 | B11: SKU5 | C11: HW-None-add-a0.2-b0.2-g0.4 | D11: 2353.5581 | E11: 3157.6619 | F11: 25.1469 | G11: Forecast | H11: =_xlfn.XLOOKUP($B11,'raw data'!$A:$A,'raw data'!F:F) -> 17971.561 | I11: =_xlfn.XLOOKUP($B11,'raw data'!$A:$A,'raw data'!G:G) -> 15494.15 | J11: =_xlfn.XLOOKUP($B11,'raw data'!$A:$A,'raw data'!H:H) -> 12490.524 | K11: =_xlfn.XLOOKUP($B11,'raw data'!$A:$A,'raw data'!I:I) -> 17414.344 | L11: =_xlfn.XLOOKUP($B11,'raw data'!$A:$A,'raw data'!J:J) -> 9431.58 | M11: =_xlfn.XLOOKUP($B11,'raw data'!$A:$A,'raw data'!K:K) -> 14568.202 | N11: =_xlfn.XLOOKUP($B11,'raw data'!$A:$A,'raw data'!L:L) -> 10676.356 | O11: =SUM(H11:N11) -> 98046.718
B12: SKU5 | G12: Pedidos | H12: 21000 | I12: 15000 | J12: 6000 | K12: 21000 | L12: 9000 | M12: 14400 | N12: 8400 | O12: =SUM(H12:N12) -> 94800
A13: 6 | B13: SKU6 | C13: HW-add-add-a0.4-b0.2-g0.6 | D13: 753.87504 | E13: 857.0794 | F13: 37.464814 | G13: Forecast | H13: =_xlfn.XLOOKUP($B13,'raw data'!$A:$A,'raw data'!F:F) -> 2527.3799 | I13: =_xlfn.XLOOKUP($B13,'raw data'!$A:$A,'raw data'!G:G) -> 4513.5879 | J13: =_xlfn.XLOOKUP($B13,'raw data'!$A:$A,'raw data'!H:H) -> 3127.2099 | K13: =_xlfn.XLOOKUP($B13,'raw data'!$A:$A,'raw data'!I:I) -> 2544.2736 | L13: =_xlfn.XLOOKUP($B13,'raw data'!$A:$A,'raw data'!J:J) -> 1728.7633 | M13: =_xlfn.XLOOKUP($B13,'raw data'!$A:$A,'raw data'!K:K) -> 4501.2911 | N13: =_xlfn.XLOOKUP($B13,'raw data'!$A:$A,'raw data'!L:L) -> 2608.3784 | O13: =SUM(H13:N13) -> 21550.884
B14: SKU6 | G14: Pedidos | H14: 2250 | I14: 3000 | J14: 3750 | K14: 2250 | L14: 750 | M14: 5100 | N14: 3600 | O14: =SUM(H14:N14) -> 20700
A15: 7 | B15: SKU7 | C15: HW-mul-mul-a0.4-b0.4-g0.6 | D15: 1956.1899 | E15: 2190.9287 | F15: 34.711814 | G15: Forecast | H15: =_xlfn.XLOOKUP($B15,'raw data'!$A:$A,'raw data'!F:F) -> 4080.1186 | I15: =_xlfn.XLOOKUP($B15,'raw data'!$A:$A,'raw data'!G:G) -> 9145.0015 | J15: =_xlfn.XLOOKUP($B15,'raw data'!$A:$A,'raw data'!H:H) -> 12825.997 | K15: =_xlfn.XLOOKUP($B15,'raw data'!$A:$A,'raw data'!I:I) -> 11036.745 | L15: =_xlfn.XLOOKUP($B15,'raw data'!$A:$A,'raw data'!J:J) -> 6690.0248 | M15: =_xlfn.XLOOKUP($B15,'raw data'!$A:$A,'raw data'!K:K) -> 13880.518 | N15: =_xlfn.XLOOKUP($B15,'raw data'!$A:$A,'raw data'!L:L) -> 9885.964 | O15: =SUM(H15:N15) -> 67544.368
B16: SKU7 | G16: Pedidos | H16: 3000 | I16: 10200 | J16: 12000 | K16: 9000 | L16: 3000 | M16: 16800 | N16: 7800 | O16: =SUM(H16:N16) -> 61800
A17: 8 | B17: SKU8 | C17: (5, 1, 2) | D17: 962.44318 | E17: 1179.1057 | F17: 45.400551 | G17: Forecast | H17: =_xlfn.XLOOKUP($B17,'raw data'!$A:$A,'raw data'!F:F) -> 1764.9263 | I17: =_xlfn.XLOOKUP($B17,'raw data'!$A:$A,'raw data'!G:G) -> 169.0685 | J17: =_xlfn.XLOOKUP($B17,'raw data'!$A:$A,'raw data'!H:H) -> 368.87776 | K17: =_xlfn.XLOOKUP($B17,'raw data'!$A:$A,'raw data'!I:I) -> 0 | L17: =_xlfn.XLOOKUP($B17,'raw data'!$A:$A,'raw data'!J:J) -> 0 | M17: =_xlfn.XLOOKUP($B17,'raw data'!$A:$A,'raw data'!K:K) -> 0 | N17: =_xlfn.XLOOKUP($B17,'raw data'!$A:$A,'raw data'!L:L) -> 1374.6047 | O17: =SUM(H17:N17) -> 3677.4773
B18: SKU8 | G18: Pedidos | H18: 5160 | I18: 4200 | J18: 600 | K18: 0 | L18: 0 | M18: 0 | N18: 0 | O18: =SUM(H18:N18) -> 9960
A19: 9 | B19: SKU9 | C19: HW-add-add-a0.4-b0.2-g0.2 | D19: 462.65279 | E19: 523.16646 | F19: 107.07261 | G19: Forecast | H19: =_xlfn.XLOOKUP($B19,'raw data'!$A:$A,'raw data'!F:F) -> 1103.0104 | I19: =_xlfn.XLOOKUP($B19,'raw data'!$A:$A,'raw data'!G:G) -> 547.12662 | J19: =_xlfn.XLOOKUP($B19,'raw data'!$A:$A,'raw data'!H:H) -> 532.8429 | K19: =_xlfn.XLOOKUP($B19,'raw data'!$A:$A,'raw data'!I:I) -> 899.00816 | L19: =_xlfn.XLOOKUP($B19,'raw data'!$A:$A,'raw data'!J:J) -> 178.32775 | M19: =_xlfn.XLOOKUP($B19,'raw data'!$A:$A,'raw data'!K:K) -> 1030.6104 | N19: =_xlfn.XLOOKUP($B19,'raw data'!$A:$A,'raw data'!L:L) -> 812.90857 | O19: =SUM(H19:N19) -> 5103.8348
B20: SKU9 | G20: Pedidos | H20: 2760 | I20: 120 | J20: 1200 | K20: 600 | L20: 420 | M20: 1200 | N20: 300 | O20: =SUM(H20:N20) -> 6600
A21: 10 | B21: SKU10 | C21: (5, 0, 3) | D21: 250.82573 | E21: 290.17226 | F21: 36.626048 | G21: Forecast | H21: =_xlfn.XLOOKUP($B21,'raw data'!$A:$A,'raw data'!F:F) -> 734.79678 | I21: =_xlfn.XLOOKUP($B21,'raw data'!$A:$A,'raw data'!G:G) -> 1291.1967 | J21: =_xlfn.XLOOKUP($B21,'raw data'!$A:$A,'raw data'!H:H) -> 868.73114 | K21: =_xlfn.XLOOKUP($B21,'raw data'!$A:$A,'raw data'!I:I) -> 1212.3203 | L21: =_xlfn.XLOOKUP($B21,'raw data'!$A:$A,'raw data'!J:J) -> 1008.7444 | M21: =_xlfn.XLOOKUP($B21,'raw data'!$A:$A,'raw data'!K:K) -> 915.78989 | N21: =_xlfn.XLOOKUP($B21,'raw data'!$A:$A,'raw data'!L:L) -> 1211.2349 | O21: =SUM(H21:N21) -> 7242.8142
B22: SKU10 | G22: Pedidos | H22: 600 | I22: 1680 | J22: 420 | K22: 1380 | L22: 600 | M22: 780 | N22: 1140 | O22: =SUM(H22:N22) -> 6600
A23: 11 | B23: SKU11 | C23: HW-None-add-a0.8-b0.2-g0.2 | D23: 232.01019 | E23: 321.73949 | F23: 21.226185 | G23: Forecast | H23: =_xlfn.XLOOKUP($B23,'raw data'!$A:$A,'raw data'!F:F) -> 666.51395 | I23: =_xlfn.XLOOKUP($B23,'raw data'!$A:$A,'raw data'!G:G) -> 1607.1162 | J23: =_xlfn.XLOOKUP($B23,'raw data'!$A:$A,'raw data'!H:H) -> 570.79605 | K23: =_xlfn.XLOOKUP($B23,'raw data'!$A:$A,'raw data'!I:I) -> 1247.4018 | L23: =_xlfn.XLOOKUP($B23,'raw data'!$A:$A,'raw data'!J:J) -> 292.20053 | M23: =_xlfn.XLOOKUP($B23,'raw data'!$A:$A,'raw data'!K:K) -> 1121.8868 | N23: =_xlfn.XLOOKUP($B23,'raw data'!$A:$A,'raw data'!L:L) -> 1369.5283 | O23: =SUM(H23:N23) -> 6875.4436
B24: SKU11 | G24: Pedidos | H24: 600 | I24: 1440 | J24: 720 | K24: 780 | L24: 300 | M24: 1020 | N24: 2460 | O24: =SUM(H24:N24) -> 7320
A25: 12 | B25: SKU12 | C25: HW-add-add-a0.6-b0.6-g0.2 | D25: 296.26054 | E25: 356.25713 | F25: 67.848572 | G25: Forecast | H25: =_xlfn.XLOOKUP($B25,'raw data'!$A:$A,'raw data'!F:F) -> 1175.1855 | I25: =_xlfn.XLOOKUP($B25,'raw data'!$A:$A,'raw data'!G:G) -> 719.44538 | J25: =_xlfn.XLOOKUP($B25,'raw data'!$A:$A,'raw data'!H:H) -> 506.09647 | K25: =_xlfn.XLOOKUP($B25,'raw data'!$A:$A,'raw data'!I:I) -> 456.61069 | L25: =_xlfn.XLOOKUP($B25,'raw data'!$A:$A,'raw data'!J:J) -> 185.90399 | M25: =_xlfn.XLOOKUP($B25,'raw data'!$A:$A,'raw data'!K:K) -> 422.46998 | N25: =_xlfn.XLOOKUP($B25,'raw data'!$A:$A,'raw data'!L:L) -> 831.0034 | O25: =SUM(H25:N25) -> 4296.7154
B26: SKU12 | G26: Pedidos | H26: 1260 | I26: 720 | J26: 1200 | K26: 0 | L26: 720 | M26: 120 | N26: 720 | O26: =SUM(H26:N26) -> 4740
A27: 13 | B27: SKU13 | C27: HW-None-add-a0.2-b0.2-g0.2 | D27: 160.97657 | E27: 194.89719 | F27: 51.351087 | G27: Forecast | H27: =_xlfn.XLOOKUP($B27,'raw data'!$A:$A,'raw data'!F:F) -> 845.68559 | I27: =_xlfn.XLOOKUP($B27,'raw data'!$A:$A,'raw data'!G:G) -> 732.09191 | J27: =_xlfn.XLOOKUP($B27,'raw data'!$A:$A,'raw data'!H:H) -> 436.82904 | K27: =_xlfn.XLOOKUP($B27,'raw data'!$A:$A,'raw data'!I:I) -> 627.5751 | L27: =_xlfn.XLOOKUP($B27,'raw data'!$A:$A,'raw data'!J:J) -> 327.05758 | M27: =_xlfn.XLOOKUP($B27,'raw data'!$A:$A,'raw data'!K:K) -> 499.62944 | N27: =_xlfn.XLOOKUP($B27,'raw data'!$A:$A,'raw data'!L:L) -> 697.8488 | O27: =SUM(H27:N27) -> 4166.7175
B28: SKU13 | G28: Pedidos | H28: 480 | I28: 900 | J28: 420 | K28: 600 | L28: 120 | M28: 300 | N28: 840 | O28: =SUM(H28:N28) -> 3660
A29: 14 | B29: SKU14 | C29: (0, 1, 1) | D29: 939.33387 | E29: 1067.3595 | F29: 115.81231 | G29: Forecast | H29: =_xlfn.XLOOKUP($B29,'raw data'!$A:$A,'raw data'!F:F) -> 2231.779 | I29: =_xlfn.XLOOKUP($B29,'raw data'!$A:$A,'raw data'!G:G) -> 2231.779 | J29: =_xlfn.XLOOKUP($B29,'raw data'!$A:$A,'raw data'!H:H) -> 2231.779 | K29: =_xlfn.XLOOKUP($B29,'raw data'!$A:$A,'raw data'!I:I) -> 2231.779 | L29: =_xlfn.XLOOKUP($B29,'raw data'!$A:$A,'raw data'!J:J) -> 2231.779 | M29: =_xlfn.XLOOKUP($B29,'raw data'!$A:$A,'raw data'!K:K) -> 2231.779 | N29: =_xlfn.XLOOKUP($B29,'raw data'!$A:$A,'raw data'!L:L) -> 2231.779 | O29: =SUM(H29:N29) -> 15622.453
B30: SKU14 | G30: Pedidos | H30: 360 | I30: 1560 | J30: 2400 | K30: 1200 | L30: 1200 | M30: 1680 | N30: 3480 | O30: =SUM(H30:N30) -> 11880
A31: 15 | B31: SKU15 | C31: HW-add-None-a0.8-b0.6-g0.2 | D31: 309.20839 | E31: 357.36822 | F31: 61.033662 | G31: Forecast | H31: =_xlfn.XLOOKUP($B31,'raw data'!$A:$A,'raw data'!F:F) -> 1057.2127 | I31: =_xlfn.XLOOKUP($B31,'raw data'!$A:$A,'raw data'!G:G) -> 943.32219 | J31: =_xlfn.XLOOKUP($B31,'raw data'!$A:$A,'raw data'!H:H) -> 829.43173 | K31: =_xlfn.XLOOKUP($B31,'raw data'!$A:$A,'raw data'!I:I) -> 715.54127 | L31: =_xlfn.XLOOKUP($B31,'raw data'!$A:$A,'raw data'!J:J) -> 601.65081 | M31: =_xlfn.XLOOKUP($B31,'raw data'!$A:$A,'raw data'!K:K) -> 487.76034 | N31: =_xlfn.XLOOKUP($B31,'raw data'!$A:$A,'raw data'!L:L) -> 373.86988 | O31: =SUM(H31:N31) -> 5008.7889
B32: SKU15 | G32: Pedidos | H32: 1200 | I32: 840 | J32: 240 | K32: 1200 | L32: 960 | M32: 600 | N32: 0 | O32: =SUM(H32:N32) -> 5040
A33: 16 | B33: SKU16 | C33: HW-None-add-a0.2-b0.2-g0.2 | D33: 661.2951 | E33: 757.71701 | F33: 76.278076 | G33: Forecast | H33: =_xlfn.XLOOKUP($B33,'raw data'!$A:$A,'raw data'!F:F) -> 3742.5275 | I33: =_xlfn.XLOOKUP($B33,'raw data'!$A:$A,'raw data'!G:G) -> 4196.0784 | J33: =_xlfn.XLOOKUP($B33,'raw data'!$A:$A,'raw data'!H:H) -> 4539.5348 | K33: =_xlfn.XLOOKUP($B33,'raw data'!$A:$A,'raw data'!I:I) -> 4098.3175 | L33: =_xlfn.XLOOKUP($B33,'raw data'!$A:$A,'raw data'!J:J) -> 0 | M33: =_xlfn.XLOOKUP($B33,'raw data'!$A:$A,'raw data'!K:K) -> 4234.6298 | N33: =_xlfn.XLOOKUP($B33,'raw data'!$A:$A,'raw data'!L:L) -> 3951.2699 | O33: =SUM(H33:N33) -> 24762.358
B34: SKU16 | G34: Pedidos | H34: 3450 | I34: 3900 | J34: 5550 | K34: 5400 | L34: 0 | M34: 3600 | N34: 3150 | O34: =SUM(H34:N34) -> 25050
A35: 17 | B35: SKU17 | C35: HW-None-add-a0.6-b0.2-g0.8 | D35: 2382.0891 | E35: 2836.6795 | F35: 30.805129 | G35: Forecast | H35: =_xlfn.XLOOKUP($B35,'raw data'!$A:$A,'raw data'!F:F) -> 5923.1248 | I35: =_xlfn.XLOOKUP($B35,'raw data'!$A:$A,'raw data'!G:G) -> 6360.1194 | J35: =_xlfn.XLOOKUP($B35,'raw data'!$A:$A,'raw data'!H:H) -> 10833.396 | K35: =_xlfn.XLOOKUP($B35,'raw data'!$A:$A,'raw data'!I:I) -> 9453.2695 | L35: =_xlfn.XLOOKUP($B35,'raw data'!$A:$A,'raw data'!J:J) -> 13288.903 | M35: =_xlfn.XLOOKUP($B35,'raw data'!$A:$A,'raw data'!K:K) -> 4005.5983 | N35: =_xlfn.XLOOKUP($B35,'raw data'!$A:$A,'raw data'!L:L) -> 20330.452 | O35: =SUM(H35:N35) -> 70194.863
B36: SKU17 | G36: Pedidos | H36: 4200 | I36: 12000 | J36: 9600 | K36: 6000 | L36: 12000 | M36: 3000 | N36: 18000 | O36: =SUM(H36:N36) -> 64800
A37: 18 | B37: SKU18 | C37: HW-add-add-a0.8-b0.4-g0.2 | D37: 612.43593 | E37: 718.28158 | F37: 66.867217 | G37: Forecast | H37: =_xlfn.XLOOKUP($B37,'raw data'!$A:$A,'raw data'!F:F) -> 1092.1316 | I37: =_xlfn.XLOOKUP($B37,'raw data'!$A:$A,'raw data'!G:G) -> 0 | J37: =_xlfn.XLOOKUP($B37,'raw data'!$A:$A,'raw data'!H:H) -> 0 | K37: =_xlfn.XLOOKUP($B37,'raw data'!$A:$A,'raw data'!I:I) -> 0 | L37: =_xlfn.XLOOKUP($B37,'raw data'!$A:$A,'raw data'!J:J) -> 0 | M37: =_xlfn.XLOOKUP($B37,'raw data'!$A:$A,'raw data'!K:K) -> 0 | N37: =_xlfn.XLOOKUP($B37,'raw data'!$A:$A,'raw data'!L:L) -> 0 | O37: =SUM(H37:N37) -> 1092.1316
B38: SKU18 | G38: Pedidos | H38: 2040 | I38: 960 | J38: 0 | K38: 0 | L38: 0 | M38: 0 | N38: 0 | O38: =SUM(H38:N38) -> 3000
A39: 19 | B39: SKU19 | C39: (4, 0, 1) | D39: 1539.8361 | E39: 1748.0411 | F39: 85.143736 | G39: Forecast | H39: =_xlfn.XLOOKUP($B39,'raw data'!$A:$A,'raw data'!F:F) -> 2521.4965 | I39: =_xlfn.XLOOKUP($B39,'raw data'!$A:$A,'raw data'!G:G) -> 3107.9216 | J39: =_xlfn.XLOOKUP($B39,'raw data'!$A:$A,'raw data'!H:H) -> 3434.6394 | K39: =_xlfn.XLOOKUP($B39,'raw data'!$A:$A,'raw data'!I:I) -> 3314.5718 | L39: =_xlfn.XLOOKUP($B39,'raw data'!$A:$A,'raw data'!J:J) -> 3204.4017 | M39: =_xlfn.XLOOKUP($B39,'raw data'!$A:$A,'raw data'!K:K) -> 3213.8287 | N39: =_xlfn.XLOOKUP($B39,'raw data'!$A:$A,'raw data'!L:L) -> 3242.1635 | O39: =SUM(H39:N39) -> 22039.023
B40: SKU19 | G40: Pedidos | H40: 1200 | I40: 4200 | J40: 3360 | K40: 1200 | L40: 1200 | M40: 1920 | N40: 6120 | O40: =SUM(H40:N40) -> 19200
A41: 20 | B41: SKU20 | C41: HW-None-add-a0.2-b0.2-g0.2 | D41: 4179.3864 | E41: 4558.8898 | F41: 110.23001 | G41: Forecast | H41: =_xlfn.XLOOKUP($B41,'raw data'!$A:$A,'raw data'!F:F) -> 9963.3559 | I41: =_xlfn.XLOOKUP($B41,'raw data'!$A:$A,'raw data'!G:G) -> 9093.2497 | J41: =_xlfn.XLOOKUP($B41,'raw data'!$A:$A,'raw data'!H:H) -> 12909.54 | K41: =_xlfn.XLOOKUP($B41,'raw data'!$A:$A,'raw data'!I:I) -> 4701.932 | L41: =_xlfn.XLOOKUP($B41,'raw data'!$A:$A,'raw data'!J:J) -> 6199.8822 | M41: =_xlfn.XLOOKUP($B41,'raw data'!$A:$A,'raw data'!K:K) -> 10294.284 | N41: =_xlfn.XLOOKUP($B41,'raw data'!$A:$A,'raw data'!L:L) -> 10520.04 | O41: =SUM(H41:N41) -> 63682.284
...

Sheet raw data
A1: SKU | B1: Best_Model | C1: MAE | D1: RMSE | E1: MAPE
A2: SKU1 | B2: HW-add-add-a0.2-b0.8-g0.2 | C2: 3925.79 | D2: 4127.5524 | E2: 25.569422 | F2: 20140.043 | G2: 14303.797 | H2: 11260.913 | I2: 19622.907 | J2: 9156.662 | K2: 26757.109 | L2: 21472.594
A3: SKU10 | B3: (5, 0, 3) | C3: 250.82573 | D3: 290.17226 | E3: 36.626048 | F3: 734.79678 | G3: 1291.1967 | H3: 868.73114 | I3: 1212.3203 | J3: 1008.7444 | K3: 915.78989 | L3: 1211.2349
A4: SKU11 | B4: HW-None-add-a0.8-b0.2-g0.2 | C4: 232.01019 | D4: 321.73949 | E4: 21.226185 | F4: 666.51395 | G4: 1607.1162 | H4: 570.79605 | I4: 1247.4018 | J4: 292.20053 | K4: 1121.8868 | L4: 1369.5283
A5: SKU12 | B5: HW-add-add-a0.6-b0.6-g0.2 | C5: 296.26054 | D5: 356.25713 | E5: 67.848572 | F5: 1175.1855 | G5: 719.44538 | H5: 506.09647 | I5: 456.61069 | J5: 185.90399 | K5: 422.46998 | L5: 831.0034
A6: SKU13 | B6: HW-None-add-a0.2-b0.2-g0.2 | C6: 160.97657 | D6: 194.89719 | E6: 51.351087 | F6: 845.68559 | G6: 732.09191 | H6: 436.82904 | I6: 627.5751 | J6: 327.05758 | K6: 499.62944 | L6: 697.8488
A7: SKU14 | B7: (0, 1, 1) | C7: 939.33387 | D7: 1067.3595 | E7: 115.81231 | F7: 2231.779 | G7: 2231.779 | H7: 2231.779 | I7: 2231.779 | J7: 2231.779 | K7: 2231.779 | L7: 2231.779
A8: SKU15 | B8: HW-add-None-a0.8-b0.6-g0.2 | C8: 309.20839 | D8: 357.36822 | E8: 61.033662 | F8: 1057.2127 | G8: 943.32219 | H8: 829.43173 | I8: 715.54127 | J8: 601.65081 | K8: 487.76034 | L8: 373.86988
A9: SKU16 | B9: HW-None-add-a0.2-b0.2-g0.2 | C9: 629.18049 | D9: 750.04872 | E9: 28.778338 | F9: 3742.5275 | G9: 4196.0784 | H9: 4539.5348 | I9: 4098.3175 | J9: 0 | K9: 4234.6298 | L9: 3951.2699
A10: SKU17 | B10: HW-None-add-a0.6-b0.2-g0.8 | C10: 2382.0891 | D10: 2836.6795 | E10: 30.805129 | F10: 5923.1248 | G10: 6360.1194 | H10: 10833.396 | I10: 9453.2695 | J10: 13288.903 | K10: 4005.5983 | L10: 20330.452
A11: SKU18 | B11: HW-add-add-a0.8-b0.2-g0.8 | C11: 272.55262 | D11: 509.90957 | E11: 73.232067 | F11: 1092.1316 | G11: 0 | H11: 0 | I11: 0 | J11: 0 | K11: 0 | L11: 0
A12: SKU19 | B12: (4, 0, 1) | C12: 1539.8361 | D12: 1748.0411 | E12: 85.143736 | F12: 2521.4965 | G12: 3107.9216 | H12: 3434.6394 | I12: 3314.5718 | J12: 3204.4017 | K12: 3213.8287 | L12: 3242.1635
A13: SKU2 | B13: HW-None-add-a0.8-b0.2-g0.2 | C13: 989.1597 | D13: 1182.2892 | E13: 34.357924 | F13: 3995.1376 | G13: 4607.4319 | H13: 3889.8667 | I13: 5076.707 | J13: 3866.023 | K13: 4787.2011 | L13: 4240.6997
... A27: SKU9 | B27: HW-add-add-a0.4-b0.2-g0.2 | C27: 462.65279 | D27: 523.16646 | E27: 107.07261 | F27: 1103.0104 | G27: 547.12662 | H27: 532.8429 | I27: 899.00816 | J27: 178.32775 | K27: 1030.6104 | L27: 812.90857
