Workbook
Name SegmentaciónDeDatos_SKU: #N/A
Name SegmentaciónDeDatos_SKU1: #N/A
Name SegmentaciónDeDatos_SKU2: #N/A

Sheet Tabla Resumen
B3: SKU | C3: Modelo Ganador | D3: Method | E3: Forecast | F3: Pedidos | G3: MAPE %
B4: SKU1 | C4: HW-add-add-a0.2-b0.2-g0.2 | D4: MAPE ST Ventana Fija | E4: 150487.96 | F4: 140520 | G4: 0.070936206
B5: SKU10 | C5: HW-add-add-a0.2-b0.2-g0.2 | D5: MAPE ST Ventana Fija | E5: 8243.8279 | F5: 9180 | G5: 0.10197953
B6: SKU11 | C6: HW-None-add-a0.8-b0.2-g0.2 | D6: MAPE ST Ventana Fija | E6: 7456.7076 | F6: 7200 | G6: 0.035653839
B7: SKU12 | C7: HW-add-add-a0.4-b0.6-g0.4 | D7: MAPE ST Ventana Fija | E7: 3699.2957 | F7: 3900 | G7: 0.051462642
B8: SKU13 | C8: HW-add-add-a0.2-b0.4-g0.2 | D8: MAPE ST Ventana Fija | E8: 3293.3699 | F8: 3900 | G8: 0.15554619
B9: SKU14 | C9: HW-None-add-a0.2-b0.2-g0.2 | D9: MAPE ST Ventana Fija | E9: 15144.397 | F9: 15840 | G9: 0.043914302
B10: SKU15 | C10: HW-add-None-a0.6-b0.8-g0.2 | D10: MAPE Regresores | E10: 6810.1749 | F10: 6960 | G10: 0.0215266
B11: SKU16 | C11: XGBRegressor | D11: MAPE ST Ventana Fija | E11: 24147.475 | F11: 24600 | G11: 0.018395307
B12: SKU17 | C12: HW-None-add-a0.2-b0.2-g0.2 | D12: MAPE ST Ventana Fija | E12: 82472.641 | F12: 82871 | G12: 0.0048069787
B13: SKU18 | C13: HW-add-add-a0.2-b0.6-g0.2 | D13: MAPE ST Ventana Fija | E13: 15586.467 | F13: 15120 | G13: 0.030850989
B14: SKU19 | C14: HW-None-None-a0.2-b0.2-g0.2 | D14: MAPE Regresores | E14: 23955 | F14: 27720 | G14: 0.13582251
B15: SKU2 | C15: KNeighborsRegressor | D15: MAPE ST Ventana Fija | E15: 32269.107 | F15: 33900 | G15: 0.048108928
... B29: SKU9 | C29: HW-add-add-a0.4-b0.8-g0.4 | D29: MAPE ST Ventana Fija | E29: 5970.1806 | F29: 7380 | G29: 0.19103244
B30: PROMEDIO DEL ERROR | G30: =AVERAGE(G4:G29) -> 0.068200686

Sheet pivot table 2
B3: Producto | C3: Forecast (Und) | D3: Pedidos (Und) | E3: WMAPE | F3: MAPE % | G3: Bias %
B4: Regresores | C4: 323476.41 | D4: 320490 | E4: 0.32022928 | F4: 0.0093182568 | G4: 0.22934967
B5: Ventana Fija ST | C5: 493497.76 | D5: 494171 | E5: 0.19476083 | F5: 0.0013623674 | G5: 0.10611855
B6: Ventana Recursiva ST | C6: 98232.792 | D6: 100800 | E6: 0.37887208 | F6: 0.025468332 | G6: 0.41569398
B7: Total general | C7: 915206.96 | D7: 915461 | E7: 0.25895777 | F7: 0.0002775019 | G7: 0.17905607

Sheet transformed data
A2: Method | B2: SKU | C2: Modelo Ganador | D2: Best_Model | E2: MAE | F2: RMSE | G2: MAPE | H2: Group | I2: WD1 | J2: WD2 | K2: WD3 | L2: WD4 | M2: WD5 | N2: WD6 | O2: WD7 | P2: Total
A3: Ventana Recursiva | B3: SKU7 | C3: HW-mul-add-a0.2-b0.8-g0.2 | D3: HW-mul-mul-a0.4-b0.4-g0.6 | E3: 1956.1899 | F3: 2190.9287 | G3: 34.711814 | H3: Forecast | I3: =_xlfn.XLOOKUP($B3,'raw data results'!$A:$A,'raw data results'!F:F) -> 9923.9197 | J3: =_xlfn.XLOOKUP($B3,'raw data results'!$A:$A,'raw data results'!G:G) -> 9901.4517 | K3: =_xlfn.XLOOKUP($B3,'raw data results'!$A:$A,'raw data results'!H:H) -> 9901.4517 | L3: =_xlfn.XLOOKUP($B3,'raw data results'!$A:$A,'raw data results'!I:I) -> 9901.4517 | M3: =_xlfn.XLOOKUP($B3,'raw data results'!$A:$A,'raw data results'!J:J) -> 9901.4517 | N3: =_xlfn.XLOOKUP($B3,'raw data results'!$A:$A,'raw data results'!K:K) -> 9901.4517 | O3: =_xlfn.XLOOKUP($B3,'raw data results'!$A:$A,'raw data results'!L:L) -> 9901.4517 | P3: =SUM(I3:O3) -> 69332.63
A4: Ventana Recursiva | B4: SKU7 | C4: HW-mul-add-a0.2-b0.8-g0.2 | H4: Pedidos | I4: 15000 | J4: 15000 | K4: 3000 | L4: 12000 | M4: 12000 | N4: 3000 | O4: 10200 | P4: =SUM(I4:O4) -> 70200
A5: Ventana Recursiva | B5: SKU21 | C5: HW-Trend(add)-seasonal(add)-a0.05-b0.07-g0.05 | D5: HW-add-add-a0.2-b0.8-g0.2 | E5: 813.81426 | F5: 1042.0188 | G5: 47.05816 | H5: Forecast | I5: =_xlfn.XLOOKUP($B5,'raw data results'!$A:$A,'raw data results'!F:F) -> 3209.199 | J5: =_xlfn.XLOOKUP($B5,'raw data results'!$A:$A,'raw data results'!G:G) -> 4301.5602 | K5: =_xlfn.XLOOKUP($B5,'raw data results'!$A:$A,'raw data results'!H:H) -> 2307.3167 | L5: =_xlfn.XLOOKUP($B5,'raw data results'!$A:$A,'raw data results'!I:I) -> 4711.069 | M5: =_xlfn.XLOOKUP($B5,'raw data results'!$A:$A,'raw data results'!J:J) -> 7662.2027 | N5: =_xlfn.XLOOKUP($B5,'raw data results'!$A:$A,'raw data results'!K:K) -> 2559.5007 | O5: =_xlfn.XLOOKUP($B5,'raw data results'!$A:$A,'raw data results'!L:L) -> 4149.3141 | P5: =SUM(I5:O5) -> 28900.162
A6: Ventana Recursiva | B6: SKU21 | C6: HW-Trend(add)-seasonal(add)-a0.05-b0.07-g0.05 | H6: Pedidos | I6: 1800 | J6: 3840 | K6: 960 | L6: 4680 | M6: 13200 | N6: 1800 | O6: 4320 | P6: =SUM(I6:O6) -> 30600
A7: Ventana Fija | B7: SKU1 | C7: HW-add-add-a0.2-b0.2-g0.2 | D7: HW-add-add-a0.2-b0.8-g0.2 | E7: 3925.79 | F7: 4127.5524 | G7: 25.569422 | H7: Forecast | I7: 14261.564 | J7: 22971.844 | K7: 11595.644 | L7: 30148.511 | M7: 25797.684 | N7: 24092.396 | O7: 21620.311 | P7: 150487.96
A8: Ventana Fija | B8: SKU1 | C8: HW-add-add-a0.2-b0.2-g0.2 | H8: Pedidos | I8: 10800 | J8: 18000 | K8: 12000 | L8: 28320 | M8: 25800 | N8: 25800 | O8: 19800 | P8: 140520
A9: Ventana Fija | B9: SKU2 | C9: KNeighborsRegressor | D9: HW-None-add-a0.8-b0.2-g0.2 | E9: 989.1597 | F9: 1182.2892 | G9: 34.357924 | H9: Forecast | I9: 4577.6308 | J9: 5177.9123 | K9: 3665.6391 | L9: 5465.6233 | M9: 4393.5975 | N9: 4452.163 | O9: 4536.5414 | P9: 32269.107
A10: Ventana Fija | B10: SKU2 | C10: KNeighborsRegressor | H10: Pedidos | I10: 6000 | J10: 7050 | K10: 6000 | L10: 5550 | M10: 4050 | N10: 2250 | O10: 3000 | P10: 33900
A11: Ventana Fija | B11: SKU5 | C11: ElasticNet | D11: HW-None-add-a0.2-b0.2-g0.4 | E11: 2353.5581 | F11: 3157.6619 | G11: 25.1469 | H11: Forecast | I11: 11803.409 | J11: 17218.71 | K11: 9561.3007 | L11: 16267.277 | M11: 13134.816 | N11: 18300.198 | O11: 16046.69 | P11: 102332.4
A12: Ventana Fija | B12: SKU5 | C12: ElasticNet | H12: Pedidos | I12: 12000 | J12: 18000 | K12: 9000 | L12: 13200 | M12: 13200 | N12: 21000 | O12: 15000 | P12: 101400
A13: Ventana Fija | B13: SKU8 | C13: ARIMA(p0-d0-q1) | D13: (5, 1, 2) | E13: 962.44318 | F13: 1179.1057 | G13: 45.400551 | H13: Forecast | I13: 607.62145 | J13: 0 | K13: 0 | L13: 914.15519 | M13: 3339.7011 | N13: 2608.9964 | O13: 1115.4247 | P13: 8585.8989
A14: Ventana Fija | B14: SKU8 | C14: ARIMA(p0-d0-q1) | H14: Pedidos | I14: 300 | J14: 600 | K14: 0 | L14: 0 | M14: 4500 | N14: 5160 | O14: 4200 | P14: 14760
A15: Ventana Fija | B15: SKU9 | C15: HW-add-add-a0.4-b0.8-g0.4 | D15: HW-add-add-a0.4-b0.2-g0.2 | E15: 462.65279 | F15: 523.16646 | G15: 107.07261 | H15: Forecast | I15: 620.54833 | J15: 795.0171 | K15: 475.80638 | L15: 1473.5051 | M15: 1246.8288 | N15: 1051.2999 | O15: 307.17503 | P15: 5970.1806
A16: Ventana Fija | B16: SKU9 | C16: HW-add-add-a0.4-b0.8-g0.4 | H16: Pedidos | I16: 0 | J16: 1680 | K16: 420 | L16: 1200 | M16: 1200 | N16: 2760 | O16: 120 | P16: 7380
A17: Ventana Fija | B17: SKU10 | C17: HW-add-add-a0.2-b0.2-g0.2 | D17: (5, 0, 3) | E17: 250.82573 | F17: 290.17226 | G17: 36.626048 | H17: Forecast | I17: 902.67276 | J17: 1147.2563 | K17: 1002.296 | L17: 1521.9648 | M17: 1436.3667 | N17: 577.69512 | O17: 1655.5762 | P17: 8243.8279
A18: Ventana Fija | B18: SKU10 | C18: HW-add-add-a0.2-b0.2-g0.2 | H18: Pedidos | I18: 1500 | J18: 1080 | K18: 1200 | L18: 1500 | M18: 1620 | N18: 600 | O18: 1680 | P18: 9180
A19: Ventana Fija | B19: SKU11 | C19: HW-None-add-a0.8-b0.2-g0.2 | D19: HW-None-add-a0.8-b0.2-g0.2 | E19: 232.01019 | F19: 321.73949 | G19: 21.226185 | H19: Forecast | I19: 1077.6363 | J19: 1633.6311 | K19: 327.36498 | L19: 675.87699 | M19: 1270.3821 | N19: 593.75069 | O19: 1878.0655 | P19: 7456.7076
A20: Ventana Fija | B20: SKU11 | C20: HW-None-add-a0.8-b0.2-g0.2 | H20: Pedidos | I20: 660 | J20: 1680 | K20: 360 | L20: 1080 | M20: 1380 | N20: 600 | O20: 1440 | P20: 7200
A21: Ventana Fija | B21: SKU12 | C21: HW-add-add-a0.4-b0.6-g0.4 | D21: HW-add-add-a0.6-b0.6-g0.2 | E21: 296.26054 | F21: 356.25713 | G21: 67.848572 | H21: Forecast | I21: 337.06929 | J21: 511.85041 | K21: 323.1176 | L21: 367.12943 | M21: 622.568 | N21: 842.73434 | O21: 694.82662 | P21: 3699.2957
A22: Ventana Fija | B22: SKU12 | C22: HW-add-add-a0.4-b0.6-g0.4 | H22: Pedidos | I22: 240 | J22: 420 | K22: 0 | L22: 600 | M22: 660 | N22: 1260 | O22: 720 | P22: 3900
A23: Ventana Fija | B23: SKU13 | C23: HW-add-add-a0.2-b0.4-g0.2 | D23: HW-None-add-a0.2-b0.2-g0.2 | E23: 160.97657 | F23: 194.89719 | G23: 51.351087 | H23: Forecast | I23: 359.167 | J23: 480.80389 | K23: 170.35752 | L23: 318.87199 | M23: 572.74755 | N23: 721.64103 | O23: 669.78088 | P23: 3293.3699
A24: Ventana Fija | B24: SKU13 | C24: HW-add-add-a0.2-b0.4-g0.2 | H24: Pedidos | I24: 120 | J24: 540 | K24: 300 | L24: 600 | M24: 960 | N24: 480 | O24: 900 | P24: 3900
A25: Ventana Fija | B25: SKU14 | C25: HW-None-add-a0.2-b0.2-g0.2 | D25: (0, 1, 1) | E25: 939.33387 | F25: 1067.3595 | G25: 115.81231 | H25: Forecast | I25: 2104.5175 | J25: 2124.1734 | K25: 2143.8294 | L25: 2163.4854 | M25: 2183.1413 | N25: 2202.7973 | O25: 2222.4532 | P25: 15144.397
A26: Ventana Fija | B26: SKU14 | C26: HW-None-add-a0.2-b0.2-g0.2 | H26: Pedidos | I26: 1800 | J26: 1200 | K26: 2040 | L26: 2040 | M26: 6840 | N26: 360 | O26: 1560 | P26: 15840
A27: Ventana Fija | B27: SKU16 | C27: XGBRegressor | D27: HW-None-add-a0.2-b0.2-g0.2 | E27: 661.2951 | F27: 757.71701 | G27: 76.278076 | H27: Forecast | I27: 4614.3798 | J27: 3591.2231 | K27: 0 | L27: 4180.0306 | M27: 3943.3371 | N27: 3734.481 | O27: 4084.0239 | P27: 24147.475
A28: Ventana Fija | B28: SKU16 | C28: XGBRegressor | H28: Pedidos | I28: 4200 | J28: 6000 | K28: 0 | L28: 4800 | M28: 2250 | N28: 3450 | O28: 3900 | P28: 24600
A29: Ventana Fija | B29: SKU17 | C29: HW-None-add-a0.2-b0.2-g0.2 | D29: HW-None-add-a0.6-b0.2-g0.8 | E29: 2382.0891 | F29: 2836.6795 | G29: 30.805129 | H29: Forecast | I29: 14752.825 | J29: 9575.0622 | K29: 8807.6743 | L29: 10301.72 | M29: 18740.737 | N29: 9626.7417 | O29: 10667.881 | P29: 82472.641
A30: Ventana Fija | B30: SKU17 | C30: HW-None-add-a0.2-b0.2-g0.2 | H30: Pedidos | I30: 13800 | J30: 9000 | K30: 15600 | L30: 12671 | M30: 15600 | N30: 4200 | O30: 12000 | P30: 82871
A31: Ventana Fija | B31: SKU18 | C31: HW-add-add-a0.2-b0.6-g0.2 | D31: HW-add-add-a0.8-b0.4-g0.2 | E31: 612.43593 | F31: 718.28158 | G31: 66.867217 | H31: Forecast | I31: 2226.6381 | J31: 2226.6381 | K31: 2226.6381 | L31: 2226.6381 | M31: 2226.6381 | N31: 2226.6381 | O31: 2226.6381 | P31: 15586.467
A32: Ventana Fija | B32: SKU18 | C32: HW-add-add-a0.2-b0.6-g0.2 | H32: Pedidos | I32: 1680 | J32: 3120 | K32: 1800 | L32: 2760 | M32: 2760 | N32: 2040 | O32: 960 | P32: 15120
A33: Ventana Fija | B33: SKU23 | C33: ElasticNet | D33: HW-add-add-a0.6-b0.6-g0.2 | E33: 845.27351 | F33: 1138.35 | G33: 30.618484 | H33: Forecast | I33: 4246.141 | J33: 5154.5191 | K33: 1972.453 | L33: 6824.2987 | M33: 6798.4114 | N33: 2406.1204 | O33: 6406.0892 | P33: 33808.033
A34: Ventana Fija | B34: SKU23 | C34: ElasticNet | H34: Pedidos | I34: 5160 | J34: 3720 | K34: 3000 | L34: 4800 | M34: 6720 | N34: 2400 | O34: 7800 | P34: 33600
A35: Regresores | B35: SKU3 | C35: ElasticNet | D35: HW-None-mul-a0.2-b0.2-g0.2 | E35: 4618.5295 | F35: 5226.9589 | G35: 64.93872 | H35: Forecast | I35: 13368.327 | J35: 14947.528 | K35: 12300.103 | L35: 15806.682 | M35: 14442.012 | N35: 9306.1655 | O35: 11884.072 | P35: =SUM(I35:O35) -> 92054.89
A36: Regresores | B36: SKU3 | C36: ElasticNet | H36: Pedidos | I36: 12000 | J36: 18000 | K36: 9000 | L36: 21000 | M36: 15000 | N36: 6000 | O36: 9000 | P36: =SUM(I36:O36) -> 90000
A37: Regresores | B37: SKU4 | C37: ElasticNet | D37: HW-add-add-a0.2-b0.2-g0.2 | E37: 1220.2418 | F37: 1466.6587 | G37: 32.756127 | H37: Forecast | I37: 4244.4325 | J37: 3350.2196 | K37: 5259.2929 | L37: 4665.2235 | M37: 5283.1008 | N37: 4704.508 | O37: 5192.3207 | P37: =SUM(I37:O37) -> 32699.098
A38: Regresores | B38: SKU4 | C38: ElasticNet | H38: Pedidos | I38: 3750 | J38: 4800 | K38: 4800 | L38: 5250 | M38: 4500 | N38: 3000 | O38: 4500 | P38: =SUM(I38:O38) -> 30600
A39: Regresores | B39: SKU6 | C39: HW-add-add-a0.2-b0.6-g0.2 | D39: HW-add-add-a0.4-b0.2-g0.6 | E39: 753.87504 | F39: 857.0794 | G39: 37.464814 | H39: Forecast | I39: 3859.7026 | J39: 3025.5938 | K39: 2359.9544 | L39: 3726.879 | M39: 2723.5092 | N39: 1955.8329 | O39: 3270.5586 | P39: =SUM(I39:O39) -> 20922.031
A40: Regresores | B40: SKU6 | C40: HW-add-add-a0.2-b0.6-g0.2 | H40: Pedidos | I40: 3750 | J40: 3300 | K40: 1500 | L40: 3900 | M40: 3150 | N40: 2250 | O40: 3000 | P40: =SUM(I40:O40) -> 20850
A41: Regresores | B41: SKU15 | C41: HW-add-None-a0.6-b0.8-g0.2 | D41: HW-add-None-a0.8-b0.6-g0.2 | E41: 309.20839 | F41: 357.36822 | G41: 61.033662 | H41: Forecast | I41: 513.68317 | J41: 533.84167 | K41: 938.74567 | L41: 1733.7327 | M41: 786.09271 | N41: 1522.7716 | O41: 781.30737 | P41: =SUM(I41:O41) -> 6810.1749
...

Sheet Hoja1
A1: Modelo | B1: Protocolo
A2: ARIMA | B2: Ventana Fija (últimos 7 días)
A3: HoltWinters | B3: Ventana Fija (últimos 7 días)
A4: XGBoost Regressor (Boosting) | B4: Ventana Recursiva (3 Semanas)
A5: Random Forest Regressor (Bagging) | B5: Ventana Recursiva (3 Semanas)
A6: Elastic Net (Modelo Lineal generalizado) | B6: Ventana Recursiva (3 Semanas)
A7: KNN Regressor (instance based model) | B7: Ventana Recursiva (3 Semanas)

Sheet pivot table
C4: Regresores | H4: Ventana Fija | M4: Ventana Recursiva
B5: Producto | C5: Forecast (Und) | D5: Pedidos (Und) | E5: WMAPE | F5: MAPE % | G5: Bias % | H5: Forecast (Und) | I5: Pedidos (Und) | J5: WMAPE | K5: MAPE % | L5: Bias % | M5: Forecast (Und) | N5: Pedidos (Und) | O5: WMAPE | P5: MAPE % | Q5: Bias %
B6: SKU1 | H6: 150487.96 | I6: 140520 | J6: 0.10102837 | K6: 0.070936206 | L6: 0.0933225
B7: SKU10 | H7: 8243.8279 | I7: 9180 | J7: 0.12141768 | K7: 0.10197953 | L7: -0.09301723
B8: SKU11 | H8: 7456.7076 | I8: 7200 | J8: 0.20204111 | K8: 0.035653839 | L8: 0.05067204
B9: SKU12 | H9: 3699.2957 | I9: 3900 | J9: 0.31404588 | K9: 0.051462642 | L9: -0.03130203
B10: SKU13 | H10: 3293.3699 | I10: 3900 | J10: 0.40211441 | K10: 0.15554619 | L10: 0.11813993
B11: SKU14 | H11: 15144.397 | I11: 15840 | J11: 0.54407291 | K11: 0.043914302 | L11: 0.84477903
B12: SKU15 | C12: 6810.1749 | D12: 6960 | E12: 0.14265225 | F12: 0.0215266 | G12: -0.021681875
B13: SKU16 | H13: 24147.475 | I13: 24600 | J13: 0.22784423 | K13: 0.018395307 | L13: 0.075046145
B14: SKU17 | H14: 82472.641 | I14: 82871 | J14: 0.24844748 | K14: 0.0048069787 | L14: 0.12756455
B15: SKU18 | H15: 15586.467 | I15: 15120 | J15: 0.29012157 | K15: 0.030850989 | L15: 0.18578243
B16: SKU19 | C16: 23955 | D16: 27720 | E16: 0.59253247 | F16: 0.13582251 | G16: 1.2132115
B17: SKU2 | H17: 32269.107 | I17: 33900 | J17: 0.2889527 | K17: 0.048108928 | L17: 0.095555629
B18: SKU20 | C18: 64601.067 | D18: 60360 | E18: 0.52528676 | F18: 0.070262867 | G18: 0.18843849
B19: SKU21 | M19: 28900.162 | N19: 30600 | O19: 0.31755322 | P19: 0.055550247 | Q19: 0.32515485
B20: SKU22 | C20: 24229.776 | D20: 25080 | E20: 0.20987311 | F20: 0.033900473 | G20: 0.20928397
B21: SKU23 | H21: 33808.033 | I21: 33600 | J21: 0.20472222 | K21: 0.0061914524 | L21: 0.017606313
B22: SKU24 | C22: 29432.424 | D22: 28560 | E22: 0.50213125 | F22: 0.030547056 | G22: 0.44462128
B23: SKU25 | C23: 14531.363 | D23: 14280 | E23: 0.20980303 | F23: 0.017602462 | G23: 0.021425839
B24: SKU26 | C24: 14240.585 | D24: 16080 | E24: 0.16583224 | F24: 0.1143915 | G24: -0.063980261
B25: SKU3 | C25: 92054.89 | D25: 90000 | E25: 0.21847162 | F25: 0.022832114 | G25: 0.12830052
B26: SKU4 | C26: 32699.098 | D26: 30600 | E26: 0.20157555 | F26: 0.068597973 | G26: 0.10145027
B27: SKU5 | H27: 102332.4 | I27: 101400 | J27: 0.083019094 | K27: 0.0091952713 | L27: 0.024461111
B28: SKU6 | C28: 20922.031 | D28: 20850 | E28: 0.11551083 | F28: 0.0034547023 | G28: 0.042723562
B29: SKU7 | M29: 69332.63 | N29: 70200 | O29: 0.40560081 | P29: 0.012355702 | Q29: 0.5062331
B30: SKU8 | H30: 8585.8989 | I30: 14760 | J30: 0.58385193 | K30: 0.41829954 | L30: -0.29224852
B31: SKU9 | H31: 5970.1806 | I31: 7380 | J31: 0.51186269 | K31: 0.19103244 | L31: 0.13562323

Sheet raw data results
A1: SKU | B1: Modelo | C1: RMSE | D1: MAE | E1: MAPE | F1: forecast
A2: SKU1 | B2: HW-Trend(add)-seasonal(add)-a0.05-b0.2-g0.25 | C2: 3274.9123 | D2: 2838.8458 | E2: 14.711003 | F2: 10722.698 | G2: 19791.58 | H2: 7896.4811 | I2: 26674.563 | J2: 22781.427 | K2: 20655.848 | L2: 15708.642
A3: SKU10 | B3: HW-Trend(add)-seasonal(add)-a0.21-b0.05-g0.16 | C3: 328.39382 | D3: 268.61977 | E3: 20.004235 | F3: 841.7593 | G3: 977.856 | H3: 812.59714 | I3: 1330.5485 | J3: 1308.2941 | K3: 516.89774 | L3: 1511.7089
A4: SKU11 | B4: HW-Trend(add)-seasonal(add)-a0.05-b0.17-g0.09 | C4: 289.10295 | D4: 251.06548 | E4: 38.330893 | F4: 970.47011 | G4: 1272.6144 | H4: 799.07759 | I4: 1215.3485 | J4: 1344.5234 | K4: 909.77353 | L4: 1559.9265
A5: SKU12 | B5: ARIMA(p1-d0-q2) | C5: 334.23517 | D5: 284.54471 | E5: 42.33237 | F5: 408.04805 | G5: 396.62441 | H5: 398.96184 | I5: 399.00847 | J5: 399.0094 | K5: 399.00941 | L5: 399.00941
A6: SKU13 | B6: HW-Trend(add)-seasonal(add)-a0.07-b0.09-g0.07 | C6: 227.37661 | D6: 193.27758 | E6: 47.603364 | F6: 316.80331 | G6: 508.79055 | H6: 219.51134 | I6: 371.38288 | J6: 581.12292 | K6: 587.92574 | L6: 570.97832
A7: SKU14 | B7: HW-Trend(add)-seasonal(add)-a0.05-b0.2-g0.05 | C7: 1759.6739 | D7: 1351.0329 | E7: 105.21916 | F7: 3070.4431 | G7: 1479.9734 | H7: 630.78047 | I7: 999.00535 | J7: 3002.1676 | K7: 2035.0564 | L7: 1585.6524
A8: SKU15 | B8: HW-Trend(add)-seasonal(add)-a0.05-b0.22-g0.11 | C8: 283.99969 | D8: 250.36003 | E8: 27.593477 | F8: 380.30852 | G8: 386.88082 | H8: 947.95083 | I8: 1559.474 | J8: 464.16648 | K8: 1268.2855 | L8: 552.88635
A9: SKU16 | B9: HW-Trend(add)-seasonal(add)-a0.35-b0.14-g0.05 | C9: 972.93094 | D9: 696.83241 | E9: 34.653231 | F9: 4351.6141 | G9: 4316.3519 | H9: 0 | I9: 4570.6986 | J9: 4057.5515 | K9: 3932.3827 | L9: 4360.4774
A10: SKU17 | B10: HW-Trend(add)-seasonal(add)-a0.05-b0.17-g0.05 | C10: 4692.5962 | D10: 3966.5833 | E10: 50.98927 | F10: 16727.342 | G10: 13113.506 | H10: 12771.114 | I10: 13427.068 | J10: 21865.396 | K10: 12930.766 | L10: 14144.119
A11: SKU18 | B11: ARIMA(p2-d0-q2) | C11: 696.88425 | D11: 539.13759 | E11: 28.814533 | F11: 2130.4072 | G11: 1712.6578 | H11: 1786.6187 | I11: 2197.8638 | J11: 2385.4526 | K11: 2140.4054 | L11: 1825.7434
A12: SKU19 | B12: HW-Trend(add)-seasonal(add)-a0.05-b0.89-g0.1 | C12: 3140.3721 | D12: 2531.1993 | E12: 59.802441 | F12: 3110.0872 | G12: 123.60084 | H12: 389.32404 | I12: 1335.8989 | J12: 2383.6359 | K12: 863.22867 | L12: 386.96358
A13: SKU2 | B13: HW-Trend(add)-seasonal(mul)-a0.05-b0.2-g0.06 | C13: 1764.5456 | D13: 1555.7702 | E13: 36.275684 | F13: 4085.8139 | G13: 4836.6027 | H13: 3246.7817 | I13: 5096.2826 | J13: 4387.6528 | K13: 4136.2052 | L13: 4332.0141
... A27: SKU9 | B27: HW-Trend(add)-seasonal(add)-a0.05-b0.2-g0.08 | C27: 954.62504 | D27: 793.16189 | E27: 266.84791 | F27: 1509.1086 | G27: 1532.0611 | H27: 1409.4255 | I27: 2022.1613 | J27: 1582.1886 | K27: 1834.2152 | L27: 1615.5038
