Workbook
Name SegmentaciónDeDatos_SKU: #N/A
Name SegmentaciónDeDatos_SKU1: #N/A
Name SegmentaciónDeDatos_SKU2: #N/A

Sheet Tabla Resumen
B3: MAPE %
B4: Producto | C4: Regresores | D4: Ventana Fija | E4: Ventana Recursiva | F4: Modelo Ganador
B5: SKU1 | C5: 0.072122636 | D5: 0.070936206 | E5: 0.11591774 | F5: HW-add-add-a0.2-b0.2-g0.2
B6: SKU10 | C6: 0.20010642 | D6: 0.10197953 | E6: 0.20482989 | F6: HW-None-add-a0.8-b0.2-g0.2
B7: SKU11 | C7: 0.058457045 | D7: 0.035653839 | E7: 0.12107417 | F7: HW-add-add-a0.4-b0.6-g0.4
B8: SKU12 | C8: 0.16530241 | D8: 0.051462642 | E8: 0.28213564 | F8: HW-add-add-a0.2-b0.4-g0.2
B9: SKU13 | C9: 0.19821875 | D9: 0.15554619 | E9: 0.19063717 | F9: HW-None-add-a0.2-b0.2-g0.2
B10: SKU14 | C10: 0.097945621 | D10: 0.043914302 | E10: 0.19172483 | F10: HW-add-None-a0.6-b0.8-g0.2
B11: SKU15 | C11: 0.0215266 | D11: 0.041638591 | E11: 0.20115625 | F11: XGBRegressor
B12: SKU16 | C12: 0.26650636 | D12: 0.018395307 | E12: 0.040206346 | F12: HW-None-add-a0.2-b0.2-g0.2
B13: SKU17 | C13: 0.012919445 | D13: 0.0048069787 | E13: 0.26677982 | F13: HW-add-add-a0.2-b0.6-g0.2
B14: SKU18 | C14: 0.087363127 | D14: 0.030850989 | E14: 0.062225599 | F14: HW-None-None-a0.2-b0.2-g0.2
B15: SKU19 | C15: 0.13582251 | D15: 0.25270827 | E15: 0.69001663 | F15: KNeighborsRegressor
B16: SKU2 | C16: 0.050579326 | D16: 0.048108928 | E16: 0.11146451 | F16: HW-None-add-a0.2-b0.2-g0.2
... B30: SKU9 | C30: 0.33931415 | D30: 0.19103244 | E30: 0.55889757 | F30: HW-None-add-a0.8-b0.2-g0.2

Sheet pivot table 2
B3: Producto | C3: Forecast (Und) | D3: Pedidos (Und) | E3: WMAPE | F3: MAPE % | G3: Bias %
B4: Regresores | C4: 919161.1 | D4: 915461 | E4: 0.26688211 | F4: 0.0040417871 | G4: 0.17345723
B5: Ventana Fija ST | C5: 901294.24 | D5: 915461 | E5: 0.24421769 | F5: 0.015475006 | G5: 0.16148926
B6: Ventana Recursiva ST | C6: 971015.61 | D6: 915461 | E6: 0.37692138 | F6: 0.060684841 | G6: 0.24408369

Sheet pivot table
C4: Regresores | H4: Ventana Fija | M4: Ventana Recursiva
B5: Producto | C5: Forecast (Und) | D5: Pedidos (Und) | E5: WMAPE | F5: MAPE % | G5: Bias % | H5: Forecast (Und) | I5: Pedidos (Und) | J5: WMAPE | K5: MAPE % | L5: Bias % | M5: Forecast (Und) | N5: Pedidos (Und) | O5: WMAPE | P5: MAPE % | Q5: Bias %
B6: SKU1 | C6: 130385.33 | D6: 140520 | E6: 0.18915755 | F6: 0.072122636 | G6: -0.017759215 | H6: 150487.96 | I6: 140520 | J6: 0.10102837 | K6: 0.070936206 | L6: 0.0933225 | M6: 124231.24 | N6: 140520 | O6: 0.14141703 | P6: 0.11591774 | Q6: -0.11867226
B7: SKU10 | C7: 7343.0231 | D7: 9180 | E7: 0.20010642 | F7: 0.20010642 | G7: -0.2045069 | H7: 8243.8279 | I7: 9180 | J7: 0.12141768 | K7: 0.10197953 | L7: -0.09301723 | M7: 7299.6616 | N7: 9180 | O7: 0.20482989 | P7: 0.20482989 | Q7: -0.20004235
B8: SKU11 | C8: 7620.8907 | D8: 7200 | E8: 0.17874121 | F8: 0.058457045 | G8: 0.16231435 | H8: 7456.7076 | I8: 7200 | J8: 0.20204111 | K8: 0.035653839 | L8: 0.05067204 | M8: 8071.7341 | N8: 7200 | O8: 0.24409144 | P8: 0.12107417 | Q8: 0.30668062
B9: SKU12 | C9: 3255.3206 | D9: 3900 | E9: 0.20366176 | F9: 0.16530241 | G9: -0.2307983 | H9: 3699.2957 | I9: 3900 | J9: 0.31404588 | K9: 0.051462642 | L9: -0.03130203 | M9: 2799.671 | N9: 3900 | O9: 0.57290995 | P9: 0.28213564 | Q9: -0.20250471
B10: SKU13 | C10: 3126.9469 | D10: 3900 | E10: 0.34165407 | F10: 0.19821875 | G10: 0.064553271 | H10: 3293.3699 | I10: 3900 | J10: 0.40211441 | K10: 0.15554619 | L10: 0.11813993 | M10: 3156.5151 | N10: 3900 | O10: 0.34690847 | P10: 0.19063717 | Q10: 0.056787179
B11: SKU14 | C11: 14288.541 | D11: 15840 | E11: 0.23921229 | F11: 0.097945621 | G11: 0.033875977 | H11: 15144.397 | I11: 15840 | J11: 0.54407291 | K11: 0.043914302 | L11: 0.84477903 | M11: 12803.079 | N11: 15840 | O11: 0.60222045 | P11: 0.19172483 | Q11: 0.54947419
B12: SKU15 | C12: 6810.1749 | D12: 6960 | E12: 0.14265225 | F12: 0.0215266 | G12: -0.021681875 | H12: 6670.1954 | I12: 6960 | J12: 0.23127212 | K12: 0.041638591 | L12: -0.050332549 | M12: 5559.9525 | N12: 6960 | O12: 0.25179888 | P12: 0.20115625 | Q12: -0.22295834
B13: SKU16 | C13: 31156.056 | D13: 24600 | E13: 0.3817819 | F13: 0.26650636 | G13: 0.15424032 | H13: 24147.475 | I13: 24600 | J13: 0.22784423 | K13: 0.018395307 | L13: 0.075046145 | M13: 25589.076 | N13: 24600 | O13: 0.1957307 | P13: 0.040206346 | Q13: 0.12816131
B14: SKU17 | C14: 83941.647 | D14: 82871 | E14: 0.19194021 | F14: 0.012919445 | G14: 0.063905893 | H14: 82472.641 | I14: 82871 | J14: 0.24844748 | K14: 0.0048069787 | L14: 0.12756455 | M14: 104979.31 | N14: 82871 | O14: 0.33505186 | P14: 0.26677982 | Q14: 0.45808159
B15: SKU18 | C15: 13799.07 | D15: 15120 | E15: 0.3251156 | F15: 0.087363127 | G15: 0.042024853 | H15: 15586.467 | I15: 15120 | J15: 0.29012157 | K15: 0.030850989 | L15: 0.18578243 | M15: 14179.149 | N15: 15120 | O15: 0.24960074 | P15: 0.062225599 | Q15: 0.060178652
B16: SKU19 | C16: 23955 | D16: 27720 | E16: 0.59253247 | F16: 0.13582251 | G16: 1.2132115 | H16: 20714.927 | I16: 27720 | J16: 0.57583601 | K16: 0.25270827 | L16: 1.616307 | M16: 8592.7391 | N16: 27720 | O16: 0.69001663 | P16: 0.69001663 | Q16: -0.60868342
B17: SKU2 | C17: 32185.361 | D17: 33900 | E17: 0.19539597 | F17: 0.050579326 | G17: 0.036157296 | H17: 32269.107 | I17: 33900 | J17: 0.2889527 | K17: 0.048108928 | L17: 0.095555629 | M17: 30121.353 | N17: 33900 | O17: 0.32125048 | P17: 0.11146451 | Q17: 0.027440074
... B31: SKU9 | C31: 9884.1384 | D31: 7380 | E31: 0.5399296 | F31: 0.33931415 | G31: 0.56949876 | H31: 5970.1806 | I31: 7380 | J31: 0.51186269 | K31: 0.19103244 | L31: 0.13562323 | M31: 11504.664 | N31: 7380 | O31: 0.84987961 | P31: 0.55889757 | Q31: 2.5664072

Sheet transformed data
A2: Method | B2: SKU | C2: Best_Model | D2: MAE | E2: RMSE | F2: MAPE | G2: Group | H2: WD1 | I2: WD2 | J2: WD3 | K2: WD4 | L2: WD5 | M2: WD6 | N2: WD7 | O2: Total
A3: Ventana Recursiva | B3: SKU1 | C3: HW-add-add-a0.2-b0.8-g0.2 | D3: 3925.79 | E3: 4127.5524 | F3: 25.569422 | G3: Forecast | H3: =_xlfn.XLOOKUP($B3,'raw data results'!$A:$A,'raw data results'!F:F) -> 10722.698 | I3: =_xlfn.XLOOKUP($B3,'raw data results'!$A:$A,'raw data results'!G:G) -> 19791.58 | J3: =_xlfn.XLOOKUP($B3,'raw data results'!$A:$A,'raw data results'!H:H) -> 7896.4811 | K3: =_xlfn.XLOOKUP($B3,'raw data results'!$A:$A,'raw data results'!I:I) -> 26674.563 | L3: =_xlfn.XLOOKUP($B3,'raw data results'!$A:$A,'raw data results'!J:J) -> 22781.427 | M3: =_xlfn.XLOOKUP($B3,'raw data results'!$A:$A,'raw data results'!K:K) -> 20655.848 | N3: =_xlfn.XLOOKUP($B3,'raw data results'!$A:$A,'raw data results'!L:L) -> 15708.642 | O3: =SUM(H3:N3) -> 124231.24
A4: Ventana Recursiva | B4: SKU1 | G4: Pedidos | H4: 10800 | I4: 18000 | J4: 12000 | K4: 28320 | L4: 25800 | M4: 25800 | N4: 19800 | O4: =SUM(H4:N4) -> 140520
A5: Ventana Recursiva | B5: SKU2 | C5: HW-None-add-a0.8-b0.2-g0.2 | D5: 989.1597 | E5: 1182.2892 | F5: 34.357924 | G5: Forecast | H5: =_xlfn.XLOOKUP($B5,'raw data results'!$A:$A,'raw data results'!F:F) -> 4085.8139 | I5: =_xlfn.XLOOKUP($B5,'raw data results'!$A:$A,'raw data results'!G:G) -> 4836.6027 | J5: =_xlfn.XLOOKUP($B5,'raw data results'!$A:$A,'raw data results'!H:H) -> 3246.7817 | K5: =_xlfn.XLOOKUP($B5,'raw data results'!$A:$A,'raw data results'!I:I) -> 5096.2826 | L5: =_xlfn.XLOOKUP($B5,'raw data results'!$A:$A,'raw data results'!J:J) -> 4387.6528 | M5: =_xlfn.XLOOKUP($B5,'raw data results'!$A:$A,'raw data results'!K:K) -> 4136.2052 | N5: =_xlfn.XLOOKUP($B5,'raw data results'!$A:$A,'raw data results'!L:L) -> 4332.0141 | O5: =SUM(H5:N5) -> 30121.353
A6: Ventana Recursiva | B6: SKU2 | G6: Pedidos | H6: 6000 | I6: 7050 | J6: 6000 | K6: 5550 | L6: 4050 | M6: 2250 | N6: 3000 | O6: =SUM(H6:N6) -> 33900
A7: Ventana Recursiva | B7: SKU3 | C7: HW-None-mul-a0.2-b0.2-g0.2 | D7: 4618.5295 | E7: 5226.9589 | F7: 64.93872 | G7: Forecast | H7: =_xlfn.XLOOKUP($B7,'raw data results'!$A:$A,'raw data results'!F:F) -> 14746.668 | I7: =_xlfn.XLOOKUP($B7,'raw data results'!$A:$A,'raw data results'!G:G) -> 13473.321 | J7: =_xlfn.XLOOKUP($B7,'raw data results'!$A:$A,'raw data results'!H:H) -> 14330.255 | K7: =_xlfn.XLOOKUP($B7,'raw data results'!$A:$A,'raw data results'!I:I) -> 13622.46 | L7: =_xlfn.XLOOKUP($B7,'raw data results'!$A:$A,'raw data results'!J:J) -> 14199.697 | M7: =_xlfn.XLOOKUP($B7,'raw data results'!$A:$A,'raw data results'!K:K) -> 13728.597 | N7: =_xlfn.XLOOKUP($B7,'raw data results'!$A:$A,'raw data results'!L:L) -> 14113.06 | O7: =SUM(H7:N7) -> 98214.058
A8: Ventana Recursiva | B8: SKU3 | G8: Pedidos | H8: 12000 | I8: 18000 | J8: 9000 | K8: 21000 | L8: 15000 | M8: 6000 | N8: 9000 | O8: =SUM(H8:N8) -> 90000
A9: Ventana Recursiva | B9: SKU4 | C9: HW-add-add-a0.2-b0.2-g0.2 | D9: 1220.2418 | E9: 1466.6587 | F9: 32.756127 | G9: Forecast | H9: =_xlfn.XLOOKUP($B9,'raw data results'!$A:$A,'raw data results'!F:F) -> 5332.2712 | I9: =_xlfn.XLOOKUP($B9,'raw data results'!$A:$A,'raw data results'!G:G) -> 5327.4007 | J9: =_xlfn.XLOOKUP($B9,'raw data results'!$A:$A,'raw data results'!H:H) -> 5357.7885 | K9: =_xlfn.XLOOKUP($B9,'raw data results'!$A:$A,'raw data results'!I:I) -> 5331.7389 | L9: =_xlfn.XLOOKUP($B9,'raw data results'!$A:$A,'raw data results'!J:J) -> 5353.0418 | M9: =_xlfn.XLOOKUP($B9,'raw data results'!$A:$A,'raw data results'!K:K) -> 5335.6676 | N9: =_xlfn.XLOOKUP($B9,'raw data results'!$A:$A,'raw data results'!L:L) -> 5349.8354 | O9: =SUM(H9:N9) -> 37387.744
A10: Ventana Recursiva | B10: SKU4 | G10: Pedidos | H10: 3750 | I10: 4800 | J10: 4800 | K10: 5250 | L10: 4500 | M10: 3000 | N10: 4500 | O10: =SUM(H10:N10) -> 30600
A11: Ventana Recursiva | B11: SKU5 | C11: HW-None-add-a0.2-b0.2-g0.4 | D11: 2353.5581 | E11: 3157.6619 | F11: 25.1469 | G11: Forecast | H11: =_xlfn.XLOOKUP($B11,'raw data results'!$A:$A,'raw data results'!F:F) -> 12218.278 | I11: =_xlfn.XLOOKUP($B11,'raw data results'!$A:$A,'raw data results'!G:G) -> 17132.901 | J11: =_xlfn.XLOOKUP($B11,'raw data results'!$A:$A,'raw data results'!H:H) -> 9528.1509 | K11: =_xlfn.XLOOKUP($B11,'raw data results'!$A:$A,'raw data results'!I:I) -> 15421.174 | L11: =_xlfn.XLOOKUP($B11,'raw data results'!$A:$A,'raw data results'!J:J) -> 12246.892 | M11: =_xlfn.XLOOKUP($B11,'raw data results'!$A:$A,'raw data results'!K:K) -> 15673.62 | N11: =_xlfn.XLOOKUP($B11,'raw data results'!$A:$A,'raw data results'!L:L) -> 14552.364 | O11: =SUM(H11:N11) -> 96773.38
A12: Ventana Recursiva | B12: SKU5 | G12: Pedidos | H12: 12000 | I12: 18000 | J12: 9000 | K12: 13200 | L12: 13200 | M12: 21000 | N12: 15000 | O12: =SUM(H12:N12) -> 101400
A13: Ventana Recursiva | B13: SKU6 | C13: HW-add-add-a0.4-b0.2-g0.6 | D13: 753.87504 | E13: 857.0794 | F13: 37.464814 | G13: Forecast | H13: =_xlfn.XLOOKUP($B13,'raw data results'!$A:$A,'raw data results'!F:F) -> 2556.4321 | I13: =_xlfn.XLOOKUP($B13,'raw data results'!$A:$A,'raw data results'!G:G) -> 3284.7062 | J13: =_xlfn.XLOOKUP($B13,'raw data results'!$A:$A,'raw data results'!H:H) -> 1467.3869 | K13: =_xlfn.XLOOKUP($B13,'raw data results'!$A:$A,'raw data results'!I:I) -> 3114.4005 | L13: =_xlfn.XLOOKUP($B13,'raw data results'!$A:$A,'raw data results'!J:J) -> 2242.1599 | M13: =_xlfn.XLOOKUP($B13,'raw data results'!$A:$A,'raw data results'!K:K) -> 2032.6655 | N13: =_xlfn.XLOOKUP($B13,'raw data results'!$A:$A,'raw data results'!L:L) -> 2453.3822 | O13: =SUM(H13:N13) -> 17151.133
A14: Ventana Recursiva | B14: SKU6 | G14: Pedidos | H14: 3750 | I14: 3300 | J14: 1500 | K14: 3900 | L14: 3150 | M14: 2250 | N14: 3000 | O14: =SUM(H14:N14) -> 20850
A15: Ventana Recursiva | B15: SKU7 | C15: HW-mul-mul-a0.4-b0.4-g0.6 | D15: 1956.1899 | E15: 2190.9287 | F15: 34.711814 | G15: Forecast | H15: =_xlfn.XLOOKUP($B15,'raw data results'!$A:$A,'raw data results'!F:F) -> 9923.9197 | I15: =_xlfn.XLOOKUP($B15,'raw data results'!$A:$A,'raw data results'!G:G) -> 9901.4517 | J15: =_xlfn.XLOOKUP($B15,'raw data results'!$A:$A,'raw data results'!H:H) -> 9901.4517 | K15: =_xlfn.XLOOKUP($B15,'raw data results'!$A:$A,'raw data results'!I:I) -> 9901.4517 | L15: =_xlfn.XLOOKUP($B15,'raw data results'!$A:$A,'raw data results'!J:J) -> 9901.4517 | M15: =_xlfn.XLOOKUP($B15,'raw data results'!$A:$A,'raw data results'!K:K) -> 9901.4517 | N15: =_xlfn.XLOOKUP($B15,'raw data results'!$A:$A,'raw data results'!L:L) -> 9901.4517 | O15: =SUM(H15:N15) -> 69332.63
A16: Ventana Recursiva | B16: SKU7 | G16: Pedidos | H16: 15000 | I16: 15000 | J16: 3000 | K16: 12000 | L16: 12000 | M16: 3000 | N16: 10200 | O16: =SUM(H16:N16) -> 70200
A17: Ventana Recursiva | B17: SKU8 | C17: (5, 1, 2) | D17: 962.44318 | E17: 1179.1057 | F17: 45.400551 | G17: Forecast | H17: =_xlfn.XLOOKUP($B17,'raw data results'!$A:$A,'raw data results'!F:F) -> 1632.7647 | I17: =_xlfn.XLOOKUP($B17,'raw data results'!$A:$A,'raw data results'!G:G) -> 0 | J17: =_xlfn.XLOOKUP($B17,'raw data results'!$A:$A,'raw data results'!H:H) -> 0 | K17: =_xlfn.XLOOKUP($B17,'raw data results'!$A:$A,'raw data results'!I:I) -> 0 | L17: =_xlfn.XLOOKUP($B17,'raw data results'!$A:$A,'raw data results'!J:J) -> 1391.4993 | M17: =_xlfn.XLOOKUP($B17,'raw data results'!$A:$A,'raw data results'!K:K) -> 793.22635 | N17: =_xlfn.XLOOKUP($B17,'raw data results'!$A:$A,'raw data results'!L:L) -> 0 | O17: =SUM(H17:N17) -> 3817.4903
A18: Ventana Recursiva | B18: SKU8 | G18: Pedidos | H18: 300 | I18: 600 | J18: 0 | K18: 0 | L18: 4500 | M18: 5160 | N18: 4200 | O18: =SUM(H18:N18) -> 14760
A19: Ventana Recursiva | B19: SKU9 | C19: HW-add-add-a0.4-b0.2-g0.2 | D19: 462.65279 | E19: 523.16646 | F19: 107.07261 | G19: Forecast | H19: =_xlfn.XLOOKUP($B19,'raw data results'!$A:$A,'raw data results'!F:F) -> 1509.1086 | I19: =_xlfn.XLOOKUP($B19,'raw data results'!$A:$A,'raw data results'!G:G) -> 1532.0611 | J19: =_xlfn.XLOOKUP($B19,'raw data results'!$A:$A,'raw data results'!H:H) -> 1409.4255 | K19: =_xlfn.XLOOKUP($B19,'raw data results'!$A:$A,'raw data results'!I:I) -> 2022.1613 | L19: =_xlfn.XLOOKUP($B19,'raw data results'!$A:$A,'raw data results'!J:J) -> 1582.1886 | M19: =_xlfn.XLOOKUP($B19,'raw data results'!$A:$A,'raw data results'!K:K) -> 1834.2152 | N19: =_xlfn.XLOOKUP($B19,'raw data results'!$A:$A,'raw data results'!L:L) -> 1615.5038 | O19: =SUM(H19:N19) -> 11504.664
A20: Ventana Recursiva | B20: SKU9 | G20: Pedidos | H20: 0 | I20: 1680 | J20: 420 | K20: 1200 | L20: 1200 | M20: 2760 | N20: 120 | O20: =SUM(H20:N20) -> 7380
A21: Ventana Recursiva | B21: SKU10 | C21: (5, 0, 3) | D21: 250.82573 | E21: 290.17226 | F21: 36.626048 | G21: Forecast | H21: =_xlfn.XLOOKUP($B21,'raw data results'!$A:$A,'raw data results'!F:F) -> 841.7593 | I21: =_xlfn.XLOOKUP($B21,'raw data results'!$A:$A,'raw data results'!G:G) -> 977.856 | J21: =_xlfn.XLOOKUP($B21,'raw data results'!$A:$A,'raw data results'!H:H) -> 812.59714 | K21: =_xlfn.XLOOKUP($B21,'raw data results'!$A:$A,'raw data results'!I:I) -> 1330.5485 | L21: =_xlfn.XLOOKUP($B21,'raw data results'!$A:$A,'raw data results'!J:J) -> 1308.2941 | M21: =_xlfn.XLOOKUP($B21,'raw data results'!$A:$A,'raw data results'!K:K) -> 516.89774 | N21: =_xlfn.XLOOKUP($B21,'raw data results'!$A:$A,'raw data results'!L:L) -> 1511.7089 | O21: =SUM(H21:N21) -> 7299.6616
A22: Ventana Recursiva | B22: SKU10 | G22: Pedidos | H22: 1500 | I22: 1080 | J22: 1200 | K22: 1500 | L22: 1620 | M22: 600 | N22: 1680 | O22: =SUM(H22:N22) -> 9180
A23: Ventana Recursiva | B23: SKU11 | C23: HW-None-add-a0.8-b0.2-g0.2 | D23: 232.01019 | E23: 321.73949 | F23: 21.226185 | G23: Forecast | H23: =_xlfn.XLOOKUP($B23,'raw data results'!$A:$A,'raw data results'!F:F) -> 970.47011 | I23: =_xlfn.XLOOKUP($B23,'raw data results'!$A:$A,'raw data results'!G:G) -> 1272.6144 | J23: =_xlfn.XLOOKUP($B23,'raw data results'!$A:$A,'raw data results'!H:H) -> 799.07759 | K23: =_xlfn.XLOOKUP($B23,'raw data results'!$A:$A,'raw data results'!I:I) -> 1215.3485 | L23: =_xlfn.XLOOKUP($B23,'raw data results'!$A:$A,'raw data results'!J:J) -> 1344.5234 | M23: =_xlfn.XLOOKUP($B23,'raw data results'!$A:$A,'raw data results'!K:K) -> 909.77353 | N23: =_xlfn.XLOOKUP($B23,'raw data results'!$A:$A,'raw data results'!L:L) -> 1559.9265 | O23: =SUM(H23:N23) -> 8071.7341
A24: Ventana Recursiva | B24: SKU11 | G24: Pedidos | H24: 660 | I24: 1680 | J24: 360 | K24: 1080 | L24: 1380 | M24: 600 | N24: 1440 | O24: =SUM(H24:N24) -> 7200
A25: Ventana Recursiva | B25: SKU12 | C25: HW-add-add-a0.6-b0.6-g0.2 | D25: 296.26054 | E25: 356.25713 | F25: 67.848572 | G25: Forecast | H25: =_xlfn.XLOOKUP($B25,'raw data results'!$A:$A,'raw data results'!F:F) -> 408.04805 | I25: =_xlfn.XLOOKUP($B25,'raw data results'!$A:$A,'raw data results'!G:G) -> 396.62441 | J25: =_xlfn.XLOOKUP($B25,'raw data results'!$A:$A,'raw data results'!H:H) -> 398.96184 | K25: =_xlfn.XLOOKUP($B25,'raw data results'!$A:$A,'raw data results'!I:I) -> 399.00847 | L25: =_xlfn.XLOOKUP($B25,'raw data results'!$A:$A,'raw data results'!J:J) -> 399.0094 | M25: =_xlfn.XLOOKUP($B25,'raw data results'!$A:$A,'raw data results'!K:K) -> 399.00941 | N25: =_xlfn.XLOOKUP($B25,'raw data results'!$A:$A,'raw data results'!L:L) -> 399.00941 | O25: =SUM(H25:N25) -> 2799.671
A26: Ventana Recursiva | B26: SKU12 | G26: Pedidos | H26: 240 | I26: 420 | J26: 0 | K26: 600 | L26: 660 | M26: 1260 | N26: 720 | O26: =SUM(H26:N26) -> 3900
A27: Ventana Recursiva | B27: SKU13 | C27: HW-None-add-a0.2-b0.2-g0.2 | D27: 160.97657 | E27: 194.89719 | F27: 51.351087 | G27: Forecast | H27: =_xlfn.XLOOKUP($B27,'raw data results'!$A:$A,'raw data results'!F:F) -> 316.80331 | I27: =_xlfn.XLOOKUP($B27,'raw data results'!$A:$A,'raw data results'!G:G) -> 508.79055 | J27: =_xlfn.XLOOKUP($B27,'raw data results'!$A:$A,'raw data results'!H:H) -> 219.51134 | K27: =_xlfn.XLOOKUP($B27,'raw data results'!$A:$A,'raw data results'!I:I) -> 371.38288 | L27: =_xlfn.XLOOKUP($B27,'raw data results'!$A:$A,'raw data results'!J:J) -> 581.12292 | M27: =_xlfn.XLOOKUP($B27,'raw data results'!$A:$A,'raw data results'!K:K) -> 587.92574 | N27: =_xlfn.XLOOKUP($B27,'raw data results'!$A:$A,'raw data results'!L:L) -> 570.97832 | O27: =SUM(H27:N27) -> 3156.5151
A28: Ventana Recursiva | B28: SKU13 | G28: Pedidos | H28: 120 | I28: 540 | J28: 300 | K28: 600 | L28: 960 | M28: 480 | N28: 900 | O28: =SUM(H28:N28) -> 3900
A29: Ventana Recursiva | B29: SKU14 | C29: (0, 1, 1) | D29: 939.33387 | E29: 1067.3595 | F29: 115.81231 | G29: Forecast | H29: =_xlfn.XLOOKUP($B29,'raw data results'!$A:$A,'raw data results'!F:F) -> 3070.4431 | I29: =_xlfn.XLOOKUP($B29,'raw data results'!$A:$A,'raw data results'!G:G) -> 1479.9734 | J29: =_xlfn.XLOOKUP($B29,'raw data results'!$A:$A,'raw data results'!H:H) -> 630.78047 | K29: =_xlfn.XLOOKUP($B29,'raw data results'!$A:$A,'raw data results'!I:I) -> 999.00535 | L29: =_xlfn.XLOOKUP($B29,'raw data results'!$A:$A,'raw data results'!J:J) -> 3002.1676 | M29: =_xlfn.XLOOKUP($B29,'raw data results'!$A:$A,'raw data results'!K:K) -> 2035.0564 | N29: =_xlfn.XLOOKUP($B29,'raw data results'!$A:$A,'raw data results'!L:L) -> 1585.6524 | O29: =SUM(H29:N29) -> 12803.079
A30: Ventana Recursiva | B30: SKU14 | G30: Pedidos | H30: 1800 | I30: 1200 | J30: 2040 | K30: 2040 | L30: 6840 | M30: 360 | N30: 1560 | O30: =SUM(H30:N30) -> 15840
A31: Ventana Recursiva | B31: SKU15 | C31: HW-add-None-a0.8-b0.6-g0.2 | D31: 309.20839 | E31: 357.36822 | F31: 61.033662 | G31: Forecast | H31: =_xlfn.XLOOKUP($B31,'raw data results'!$A:$A,'raw data results'!F:F) -> 380.30852 | I31: =_xlfn.XLOOKUP($B31,'raw data results'!$A:$A,'raw data results'!G:G) -> 386.88082 | J31: =_xlfn.XLOOKUP($B31,'raw data results'!$A:$A,'raw data results'!H:H) -> 947.95083 | K31: =_xlfn.XLOOKUP($B31,'raw data results'!$A:$A,'raw data results'!I:I) -> 1559.474 | L31: =_xlfn.XLOOKUP($B31,'raw data results'!$A:$A,'raw data results'!J:J) -> 464.16648 | M31: =_xlfn.XLOOKUP($B31,'raw data results'!$A:$A,'raw data results'!K:K) -> 1268.2855 | N31: =_xlfn.XLOOKUP($B31,'raw data results'!$A:$A,'raw data results'!L:L) -> 552.88635 | O31: =SUM(H31:N31) -> 5559.9525
A32: Ventana Recursiva | B32: SKU15 | G32: Pedidos | H32: 600 | I32: 600 | J32: 840 | K32: 2040 | L32: 840 | M32: 1200 | N32: 840 | O32: =SUM(H32:N32) -> 6960
A33: Ventana Recursiva | B33: SKU16 | C33: HW-None-add-a0.2-b0.2-g0.2 | D33: 661.2951 | E33: 757.71701 | F33: 76.278076 | G33: Forecast | H33: =_xlfn.XLOOKUP($B33,'raw data results'!$A:$A,'raw data results'!F:F) -> 4351.6141 | I33: =_xlfn.XLOOKUP($B33,'raw data results'!$A:$A,'raw data results'!G:G) -> 4316.3519 | J33: =_xlfn.XLOOKUP($B33,'raw data results'!$A:$A,'raw data results'!H:H) -> 0 | K33: =_xlfn.XLOOKUP($B33,'raw data results'!$A:$A,'raw data results'!I:I) -> 4570.6986 | L33: =_xlfn.XLOOKUP($B33,'raw data results'!$A:$A,'raw data results'!J:J) -> 4057.5515 | M33: =_xlfn.XLOOKUP($B33,'raw data results'!$A:$A,'raw data results'!K:K) -> 3932.3827 | N33: =_xlfn.XLOOKUP($B33,'raw data results'!$A:$A,'raw data results'!L:L) -> 4360.4774 | O33: =SUM(H33:N33) -> 25589.076
A34: Ventana Recursiva | B34: SKU16 | G34: Pedidos | H34: 4200 | I34: 6000 | J34: 0 | K34: 4800 | L34: 2250 | M34: 3450 | N34: 3900 | O34: =SUM(H34:N34) -> 24600
A35: Ventana Recursiva | B35: SKU17 | C35: HW-None-add-a0.6-b0.2-g0.8 | D35: 2382.0891 | E35: 2836.6795 | F35: 30.805129 | G35: Forecast | H35: =_xlfn.XLOOKUP($B35,'raw data results'!$A:$A,'raw data results'!F:F) -> 16727.342 | I35: =_xlfn.XLOOKUP($B35,'raw data results'!$A:$A,'raw data results'!G:G) -> 13113.506 | J35: =_xlfn.XLOOKUP($B35,'raw data results'!$A:$A,'raw data results'!H:H) -> 12771.114 | K35: =_xlfn.XLOOKUP($B35,'raw data results'!$A:$A,'raw data results'!I:I) -> 13427.068 | L35: =_xlfn.XLOOKUP($B35,'raw data results'!$A:$A,'raw data results'!J:J) -> 21865.396 | M35: =_xlfn.XLOOKUP($B35,'raw data results'!$A:$A,'raw data results'!K:K) -> 12930.766 | N35: =_xlfn.XLOOKUP($B35,'raw data results'!$A:$A,'raw data results'!L:L) -> 14144.119 | O35: =SUM(H35:N35) -> 104979.31
A36: Ventana Recursiva | B36: SKU17 | G36: Pedidos | H36: 13800 | I36: 9000 | J36: 15600 | K36: 12671 | L36: 15600 | M36: 4200 | N36: 12000 | O36: =SUM(H36:N36) -> 82871
A37: Ventana Recursiva | B37: SKU18 | C37: HW-add-add-a0.8-b0.4-g0.2 | D37: 612.43593 | E37: 718.28158 | F37: 66.867217 | G37: Forecast | H37: =_xlfn.XLOOKUP($B37,'raw data results'!$A:$A,'raw data results'!F:F) -> 2130.4072 | I37: =_xlfn.XLOOKUP($B37,'raw data results'!$A:$A,'raw data results'!G:G) -> 1712.6578 | J37: =_xlfn.XLOOKUP($B37,'raw data results'!$A:$A,'raw data results'!H:H) -> 1786.6187 | K37: =_xlfn.XLOOKUP($B37,'raw data results'!$A:$A,'raw data results'!I:I) -> 2197.8638 | L37: =_xlfn.XLOOKUP($B37,'raw data results'!$A:$A,'raw data results'!J:J) -> 2385.4526 | M37: =_xlfn.XLOOKUP($B37,'raw data results'!$A:$A,'raw data results'!K:K) -> 2140.4054 | N37: =_xlfn.XLOOKUP($B37,'raw data results'!$A:$A,'raw data results'!L:L) -> 1825.7434 | O37: =SUM(H37:N37) -> 14179.149
A38: Ventana Recursiva | B38: SKU18 | G38: Pedidos | H38: 1680 | I38: 3120 | J38: 1800 | K38: 2760 | L38: 2760 | M38: 2040 | N38: 960 | O38: =SUM(H38:N38) -> 15120
A39: Ventana Recursiva | B39: SKU19 | C39: (4, 0, 1) | D39: 1539.8361 | E39: 1748.0411 | F39: 85.143736 | G39: Forecast | H39: =_xlfn.XLOOKUP($B39,'raw data results'!$A:$A,'raw data results'!F:F) -> 3110.0872 | I39: =_xlfn.XLOOKUP($B39,'raw data results'!$A:$A,'raw data results'!G:G) -> 123.60084 | J39: =_xlfn.XLOOKUP($B39,'raw data results'!$A:$A,'raw data results'!H:H) -> 389.32404 | K39: =_xlfn.XLOOKUP($B39,'raw data results'!$A:$A,'raw data results'!I:I) -> 1335.8989 | L39: =_xlfn.XLOOKUP($B39,'raw data results'!$A:$A,'raw data results'!J:J) -> 2383.6359 | M39: =_xlfn.XLOOKUP($B39,'raw data results'!$A:$A,'raw data results'!K:K) -> 863.22867 | N39: =_xlfn.XLOOKUP($B39,'raw data results'!$A:$A,'raw data results'!L:L) -> 386.96358 | O39: =SUM(H39:N39) -> 8592.7391
A40: Ventana Recursiva | B40: SKU19 | G40: Pedidos | H40: 8400 | I40: 240 | J40: 4200 | K40: 6240 | L40: 3240 | M40: 1200 | N40: 4200 | O40: =SUM(H40:N40) -> 27720
A41: Ventana Recursiva | B41: SKU20 | C41: HW-None-add-a0.2-b0.2-g0.2 | D41: 4179.3864 | E41: 4558.8898 | F41: 110.23001 | G41: Forecast | H41: =_xlfn.XLOOKUP($B41,'raw data results'!$A:$A,'raw data results'!F:F) -> 16788.947 | I41: =_xlfn.XLOOKUP($B41,'raw data results'!$A:$A,'raw data results'!G:G) -> 11673.282 | J41: =_xlfn.XLOOKUP($B41,'raw data results'!$A:$A,'raw data results'!H:H) -> 16986.196 | K41: =_xlfn.XLOOKUP($B41,'raw data results'!$A:$A,'raw data results'!I:I) -> 23660.923 | L41: =_xlfn.XLOOKUP($B41,'raw data results'!$A:$A,'raw data results'!J:J) -> 27237.407 | M41: =_xlfn.XLOOKUP($B41,'raw data results'!$A:$A,'raw data results'!K:K) -> 27377.365 | N41: =_xlfn.XLOOKUP($B41,'raw data results'!$A:$A,'raw data results'!L:L) -> 29362.436 | O41: =SUM(H41:N41) -> 153086.56
...

Sheet raw data results
A1: SKU | B1: Modelo | C1: RMSE | D1: MAE | E1: MAPE | F1: forecast
A2: SKU1 | B2: HW-Trend(add)-seasonal(add)-a0.05-b0.2-g0.25 | C2: 3274.9123 | D2: 2838.8458 | E2: 14.711003 | F2: 10722.698 | G2: 19791.58 | H2: 7896.4811 | I2: 26674.563 | J2: 22781.427 | K2: 20655.848 | L2: 15708.642
A3: SKU10 | B3: HW-Trend(add)-seasonal(add)-a0.21-b0.05-g0.16 | C3: 328.39382 | D3: 268.61977 | E3: 20.004235 | F3: 841.7593 | G3: 977.856 | H3: 812.59714 | I3: 1330.5485 | J3: 1308.2941 | K3: 516.89774 | L3: 1511.7089
A4: SKU11 | B4: HW-Trend(add)-seasonal(add)-a0.05-b0.17-g0.09 | C4: 289.10295 | D4: 251.06548 | E4: 38.330893 | F4: 970.47011 | G4: 1272.6144 | H4: 799.07759 | I4: 1215.3485 | J4: 1344.5234 | K4: 909.77353 | L4: 1559.9265
A5: SKU12 | B5: ARIMA(p1-d0-q2) | C5: 334.23517 | D5: 284.54471 | E5: 42.33237 | F5: 408.04805 | G5: 396.62441 | H5: 398.96184 | I5: 399.00847 | J5: 399.0094 | K5: 399.00941 | L5: 399.00941
A6: SKU13 | B6: HW-Trend(add)-seasonal(add)-a0.07-b0.09-g0.07 | C6: 227.37661 | D6: 193.27758 | E6: 47.603364 | F6: 316.80331 | G6: 508.79055 | H6: 219.51134 | I6: 371.38288 | J6: 581.12292 | K6: 587.92574 | L6: 570.97832
A7: SKU14 | B7: HW-Trend(add)-seasonal(add)-a0.05-b0.2-g0.05 | C7: 1759.6739 | D7: 1351.0329 | E7: 105.21916 | F7: 3070.4431 | G7: 1479.9734 | H7: 630.78047 | I7: 999.00535 | J7: 3002.1676 | K7: 2035.0564 | L7: 1585.6524
A8: SKU15 | B8: HW-Trend(add)-seasonal(add)-a0.05-b0.22-g0.11 | C8: 283.99969 | D8: 250.36003 | E8: 27.593477 | F8: 380.30852 | G8: 386.88082 | H8: 947.95083 | I8: 1559.474 | J8: 464.16648 | K8: 1268.2855 | L8: 552.88635
A9: SKU16 | B9: HW-Trend(add)-seasonal(add)-a0.35-b0.14-g0.05 | C9: 972.93094 | D9: 696.83241 | E9: 34.653231 | F9: 4351.6141 | G9: 4316.3519 | H9: 0 | I9: 4570.6986 | J9: 4057.5515 | K9: 3932.3827 | L9: 4360.4774
A10: SKU17 | B10: HW-Trend(add)-seasonal(add)-a0.05-b0.17-g0.05 | C10: 4692.5962 | D10: 3966.5833 | E10: 50.98927 | F10: 16727.342 | G10: 13113.506 | H10: 12771.114 | I10: 13427.068 | J10: 21865.396 | K10: 12930.766 | L10: 14144.119
A11: SKU18 | B11: ARIMA(p2-d0-q2) | C11: 696.88425 | D11: 539.13759 | E11: 28.814533 | F11: 2130.4072 | G11: 1712.6578 | H11: 1786.6187 | I11: 2197.8638 | J11: 2385.4526 | K11: 2140.4054 | L11: 1825.7434
A12: SKU19 | B12: HW-Trend(add)-seasonal(add)-a0.05-b0.89-g0.1 | C12: 3140.3721 | D12: 2531.1993 | E12: 59.802441 | F12: 3110.0872 | G12: 123.60084 | H12: 389.32404 | I12: 1335.8989 | J12: 2383.6359 | K12: 863.22867 | L12: 386.96358
A13: SKU2 | B13: HW-Trend(add)-seasonal(mul)-a0.05-b0.2-g0.06 | C13: 1764.5456 | D13: 1555.7702 | E13: 36.275684 | F13: 4085.8139 | G13: 4836.6027 | H13: 3246.7817 | I13: 5096.2826 | J13: 4387.6528 | K13: 4136.2052 | L13: 4332.0141
... A27: SKU9 | B27: HW-Trend(add)-seasonal(add)-a0.05-b0.2-g0.08 | C27: 954.62504 | D27: 793.16189 | E27: 266.84791 | F27: 1509.1086 | G27: 1532.0611 | H27: 1409.4255 | I27: 2022.1613 | J27: 1582.1886 | K27: 1834.2152 | L27: 1615.5038
